Workbook

Sheet 요약
A1: 2026년 10월 광고 성과 및 11~12월 목표 · 아넬라 / 로지오가닉
A2: ="집계 "&TEXT('가정'!B5,"yyyy.mm.dd")&" ~ "&TEXT('가정'!B6,"mm.dd")&" ("&'가정'!B7&"일) · 월말 예상은 10/26~28 일평균 기준 · 금액 단위 만원 · 네이버 VAT 미포함 · 매출은 매체 구매 귀속 기준"
A4: 1. 한눈에 보기
A5: ="· 아넬라: 28일 ROAS "&TEXT('10월_실적'!G31,"#,##0%")&"로 KPI 하한("&TEXT('10월_실적'!C31,"0%")&")의 "&TEXT('10월_실적'!H31,"0%")&". 월말 예상 ROAS "&TEXT('10월_실적'!D38,"#,##0%")&"이나 예산은 일할 대비 "&TEXT('10월_실적'!E13,"0%")&"만 사용했습니다."
A6: ="· 로지오가닉: 28일 ROAS "&TEXT('10월_실적'!G32,"#,##0%")&"로 하한("&TEXT('10월_실적'!C32,"0%")&")의 "&TEXT('10월_실적'!H32,"0%")&". 메타 스스 이상치 이틀을 빼도 "&TEXT('10월_실적'!D46,"#,##0%")&"로 하한을 넘습니다."
A7: ="· 아넬라는 행사 구간 ROAS("&TEXT('주차별_추이'!I11,"#,##0%")&")가 상시 구간("&TEXT('주차별_추이'!H11,"#,##0%")&")의 "&TEXT('주차별_추이'!I11/'주차별_추이'!H11,"0.0")&"배라, 11월 목표는 행사 일정에 좌우됩니다. 하한 달성에 필요한 행사일수는 약 "&TEXT('목표_11-12월'!O30,"0.0")&"일(11월)입니다."
A9: 2. 10월 실적과 목표(소급) 대비
A10: 브랜드 | B10: 광고비 | C10: 매출 | D10: ROAS | E10: KPI 하한 | F10: ROAS 달성률 | G10: 월말 예상 ROAS | H10: 월말 예상 매출 ÷ 목표 | I10: 구매(건) | J10: 스토어 일반 순매출 | K10: 28일 판정
A11: 아넬라 | B11: ='10월_실적'!E31 | C11: ='10월_실적'!F31 | D11: ='10월_실적'!G31 | E11: ='10월_실적'!C31 | F11: ='10월_실적'!H31 | G11: ='10월_실적'!D38 | H11: ='10월_실적'!F38 | I11: ='10월_실적'!J13 | J11: ='주차별_추이'!G17/10000 | K11: ='10월_실적'!I31
A12: 로지오가닉 | B12: ='10월_실적'!E32 | C12: ='10월_실적'!F32 | D12: ='10월_실적'!G32 | E12: ='10월_실적'!C32 | F12: ='10월_실적'!H32 | G12: ='10월_실적'!D39 | H12: ='10월_실적'!F39 | I12: ='10월_실적'!J25 | J12: ='주차별_추이'!G38/10000 | K12: ='10월_실적'!I32
A13: 합계 | B13: =B11+B12 | C13: =C11+C12 | D13: =IF(B13=0,0,C13/B13) | E13: ='10월_실적'!C33 | F13: ='10월_실적'!H33 | G13: ='10월_실적'!D40 | H13: ='10월_실적'!F40 | I13: =I11+I12 | J13: =J11+J12 | K13: ='10월_실적'!I33
A14: 10월 목표가 따로 없어 4분기 KPI 보고안의 ROAS 하한(아넬라 850%, 로지 420%)과 10월 광고예산을 소급 적용했습니다. 스토어 일반 순매출은 공동구매 상품을 제외한 값입니다.
A16: 3. 매체별 ROAS와 광고비 (10/1~10/28)
A17: 매체 | B17: 아넬라 광고비 | C17: 아넬라 매출 | D17: 아넬라 ROAS | E17: 로지 광고비 | F17: 로지 매출 | G17: 로지 ROAS
A18: 파워링크 | B18: ='10월_실적'!D6 | C18: ='10월_실적'!L6 | D18: ='10월_실적'!M6 | E18: ='10월_실적'!D18 | F18: ='10월_실적'!L18 | G18: ='10월_실적'!M18
A19: 쇼핑검색 | B19: ='10월_실적'!D7 | C19: ='10월_실적'!L7 | D19: ='10월_실적'!M7 | E19: ='10월_실적'!D19 | F19: ='10월_실적'!L19 | G19: ='10월_실적'!M19
A20: 브랜드검색 | B20: ='10월_실적'!D8 | C20: ='10월_실적'!L8 | D20: ='10월_실적'!M8 | E20: ='10월_실적'!D20 | F20: ='10월_실적'!L20 | G20: ='10월_실적'!M20
A21: GFA 카탈로그 | B21: ='10월_실적'!D9 | C21: ='10월_실적'!L9 | D21: ='10월_실적'!M9 | E21: ='10월_실적'!D21 | F21: ='10월_실적'!L21 | G21: ='10월_실적'!M21
A22: GFA 전환 | B22: ='10월_실적'!D10 | C22: ='10월_실적'!L10 | D22: ='10월_실적'!M10 | E22: ='10월_실적'!D22 | F22: ='10월_실적'!L22 | G22: ='10월_실적'!M22
A23: 메타 스스 | B23: ='10월_실적'!D11 | C23: ='10월_실적'!L11 | D23: ='10월_실적'!M11 | E23: ='10월_실적'!D23 | F23: ='10월_실적'!L23 | G23: ='10월_실적'!M23
A24: 메타 자사몰 | B24: ='10월_실적'!D12 | C24: ='10월_실적'!L12 | D24: ='10월_실적'!M12 | E24: ='10월_실적'!D24 | F24: ='10월_실적'!L24 | G24: ='10월_실적'!M24
A25: 합계 | B25: =SUM(B18:B24) | C25: =SUM(C18:C24) | D25: =IF(B25=0,0,C25/B25) | E25: =SUM(E18:E24) | F25: =SUM(F18:F24) | G25: =IF(E25=0,0,F25/E25)
A26: 브랜드검색 ROAS는 월 정액 대비 값입니다. GFA 전환 로지오가닉은 10/26부터 집행했습니다.
A28: 4. 잘한 점 · 성과 이유 / 미달 · 보완
A29: ="· 아넬라 파워링크 노출 시간 제한(10/14~): 행사가 없는 두 주를 비교하면 광고비 "&TEXT('시간제한_검증'!E7,"+0%;-0%")&"인데 구매는 "&'시간제한_검증'!B10&"건에서 "&'시간제한_검증'!C10&"건으로 유지되고 ROAS는 "&TEXT('시간제한_검증'!B13,"#,##0%")&"에서 "&TEXT('시간제한_검증'!C13,"#,##0%")&"로 올랐습니다."
A30: ="· 아넬라 저효율 키워드·지면 정리와 시간 제한으로 일할 예산의 "&TEXT('10월_실적'!E13,"0%")&"만 집행하고도 ROAS가 하한에 근접("&TEXT('10월_실적'!H31,"0%")&")했습니다. 상시 구간에서는 쇼핑검색(ROAS "&TEXT('주차별_추이'!H49,"#,##0%")&")이 파워링크("&TEXT('주차별_추이'!H48,"#,##0%")&")보다 효율이 높았습니다."
A31: ="· 메타 시크릿링크가 자사몰 매출의 주축입니다. 시크릿특가 상품이 자사몰 매출의 아넬라 "&TEXT('자사몰_매출'!H7,"0%")&", 로지 "&TEXT('자사몰_매출'!H8,"0%")&"를 차지하고, 시크릿특가 매출 기준 ROAS는 아넬라 "&TEXT('자사몰_매출'!G15,"#,##0%")&", 로지 "&TEXT('자사몰_매출'!G16,"#,##0%")&"입니다."
A32: ="· 로지오가닉은 행사 영향이 작은 가운데 하한을 상회(ROAS "&TEXT('10월_실적'!G32,"#,##0%")&", 이상치 제외 "&TEXT('10월_실적'!D46,"#,##0%")&")했고, 메타 자사몰 과자 시크릿링크가 10월 내내 안정적("&TEXT('10월_실적'!M24,"#,##0%")&")이었습니다."
A33: ="· 아넬라 상시 구간 ROAS "&TEXT('주차별_추이'!H11,"#,##0%")&"로 하한("&TEXT('10월_실적'!C31,"0%")&")의 절반 수준. 4주차(10/19~25)는 전 매체 ROAS가 하락했습니다. 보완: 상시 소재 교체, 시간대 입찰 원복 검토, 저효율 정리 효과 검증."
A34: ="· 아넬라 메타 자사몰·카탈로그 효율 하락. 웰컴박스·기획전은 보류 유지, 시크릿링크는 개편 썸네일로 교체, 카탈로그는 주력 상품 중심으로 재구성."
A35: ="· 로지오가닉 파워링크+쇼핑검색 합산 ROAS "&TEXT('성과분석'!E20,"#,##0%")&"로 하한 미달. 보완: 파워링크 대표K·구매K 점검, 11/8 이후 상시 구간으로 감액 효과 검증."
A36: ="· 로지오가닉 메타 스스 10/24~25 전환값이 같은 이틀 스토어 결제의 "&TEXT('점검'!D15,"0.0")&"배. 집계 이슈 가능성이 있어 확인 전까지 목표 산정에서 제외했습니다."
A38: 5. 11~12월 목표 (광고비는 확정 예산, 목표 매출은 행사일수 가정에 따른 시나리오)
A39: 브랜드 | B39: 월 | C39: 광고비 | D39: 목표 ROAS 보수 | E39: 목표 ROAS 기준 | F39: 목표 ROAS 도전 | G39: 목표 매출 보수 | H39: 목표 매출 기준 | I39: 목표 매출 도전 | J39: KPI 하한 | K39: 하한 달성 필요 행사일수
A40: 아넬라 | B40: 11월 | C40: ='목표_11-12월'!K19 | D40: ='목표_11-12월'!L19 | E40: ='목표_11-12월'!M19 | F40: ='목표_11-12월'!N19 | G40: ='목표_11-12월'!O19 | H40: ='목표_11-12월'!P19 | I40: ='목표_11-12월'!Q19 | J40: ='목표_11-12월'!B30 | K40: ='목표_11-12월'!O30
A41: 아넬라 | B41: 12월 | C41: ='목표_11-12월'!K43 | D41: ='목표_11-12월'!L43 | E41: ='목표_11-12월'!M43 | F41: ='목표_11-12월'!N43 | G41: ='목표_11-12월'!O43 | H41: ='목표_11-12월'!P43 | I41: ='목표_11-12월'!Q43 | J41: ='목표_11-12월'!B54 | K41: ='목표_11-12월'!O54
A42: 로지오가닉 | B42: 11월 | C42: ='목표_11-12월'!K27 | D42: ='목표_11-12월'!L27 | E42: ='목표_11-12월'!M27 | F42: ='목표_11-12월'!N27 | G42: ='목표_11-12월'!O27 | H42: ='목표_11-12월'!P27 | I42: ='목표_11-12월'!Q27 | J42: ='목표_11-12월'!B31 | K42: ='목표_11-12월'!O31
A43: 로지오가닉 | B43: 12월 | C43: ='목표_11-12월'!K51 | D43: ='목표_11-12월'!L51 | E43: ='목표_11-12월'!M51 | F43: ='목표_11-12월'!N51 | G43: ='목표_11-12월'!O51 | H43: ='목표_11-12월'!P51 | I43: ='목표_11-12월'!Q51 | J43: ='목표_11-12월'!B55 | K43: ='목표_11-12월'!O55
A44: ="가정: 11월 행사일수 "&'목표_11-12월'!B6&"/"&'목표_11-12월'!C6&"/"&'목표_11-12월'!D6&"일(보수/기준/도전), 12월 "&'목표_11-12월'!B7&"/"&'목표_11-12월'!C7&"/"&'목표_11-12월'!D7&"일. 11월 확정은 넾다세일 8일뿐이고 나머지는 영업팀 일정에 따라 수정합니다."
A45: ="스마트스토어 일반상품 순매출 목표(기준, 공구 제외): 아넬라 11월 "&TEXT('목표_11-12월'!J60,"#,##0")&"만원, 12월 "&TEXT('목표_11-12월'!J61,"#,##0")&"만원 / 로지오가닉 11월 "&TEXT('목표_11-12월'!J62,"#,##0")&"만원, 12월 "&TEXT('목표_11-12월'!J63,"#,##0")&"만원"
...

Sheet 10월_실적
A1: 10월 광고 실적 (10/1~10/28) 및 목표 대비 달성률
A2: 금액 단위 만원(별도 표기 제외). 10월 목표는 별도로 세워진 것이 없어, 4분기 KPI 보고안의 ROAS 하한과 10월 광고예산을 적용한 소급 기준입니다.
A4: 아넬라
A5: 매체 | B5: 10월 월예산 | C5: 일할 예산 | D5: 광고비 | E5: 일할 대비 소진율 | F5: 노출 | G5: 클릭 | H5: CTR | I5: CPC(원) | J5: 구매(건) | K5: CVR | L5: 매출 | M5: ROAS | N5: CPA(원) | O5: 광고비 비중 | P5: 매출 비중
A6: 파워링크 | B6: =SUMIFS('가정'!$C$16:$C$27,'가정'!$A$16:$A$27,$A$4,'가정'!$B$16:$B$27,$A6) | C6: =B6*'가정'!$B$7/'가정'!$B$8 | D6: =SUMIFS('데이터_광고'!$E$2:$E$500,'데이터_광고'!$A$2:$A$500,$A$4,'데이터_광고'!$B$2:$B$500,$A6)/10000 | E6: =IF(C6=0,0,D6/C6) | F6: =SUMIFS('데이터_광고'!$F$2:$F$500,'데이터_광고'!$A$2:$A$500,$A$4,'데이터_광고'!$B$2:$B$500,$A6) | G6: =SUMIFS('데이터_광고'!$G$2:$G$500,'데이터_광고'!$A$2:$A$500,$A$4,'데이터_광고'!$B$2:$B$500,$A6) | H6: =IF(F6=0,0,G6/F6) | I6: =IF(G6=0,0,D6*10000/G6) | J6: =SUMIFS('데이터_광고'!$H$2:$H$500,'데이터_광고'!$A$2:$A$500,$A$4,'데이터_광고'!$B$2:$B$500,$A6) | K6: =IF(G6=0,0,J6/G6) | L6: =SUMIFS('데이터_광고'!$I$2:$I$500,'데이터_광고'!$A$2:$A$500,$A$4,'데이터_광고'!$B$2:$B$500,$A6)/10000 | M6: =IF(D6=0,0,L6/D6) | N6: =IF(J6=0,0,D6*10000/J6) | O6: =IF(D$13=0,0,D6/D$13) | P6: =IF(L$13=0,0,L6/L$13)
A7: 쇼핑검색 | B7: =SUMIFS('가정'!$C$16:$C$27,'가정'!$A$16:$A$27,$A$4,'가정'!$B$16:$B$27,$A7) | C7: =B7*'가정'!$B$7/'가정'!$B$8 | D7: =SUMIFS('데이터_광고'!$E$2:$E$500,'데이터_광고'!$A$2:$A$500,$A$4,'데이터_광고'!$B$2:$B$500,$A7)/10000 | E7: =IF(C7=0,0,D7/C7) | F7: =SUMIFS('데이터_광고'!$F$2:$F$500,'데이터_광고'!$A$2:$A$500,$A$4,'데이터_광고'!$B$2:$B$500,$A7) | G7: =SUMIFS('데이터_광고'!$G$2:$G$500,'데이터_광고'!$A$2:$A$500,$A$4,'데이터_광고'!$B$2:$B$500,$A7) | H7: =IF(F7=0,0,G7/F7) | I7: =IF(G7=0,0,D7*10000/G7) | J7: =SUMIFS('데이터_광고'!$H$2:$H$500,'데이터_광고'!$A$2:$A$500,$A$4,'데이터_광고'!$B$2:$B$500,$A7) | K7: =IF(G7=0,0,J7/G7) | L7: =SUMIFS('데이터_광고'!$I$2:$I$500,'데이터_광고'!$A$2:$A$500,$A$4,'데이터_광고'!$B$2:$B$500,$A7)/10000 | M7: =IF(D7=0,0,L7/D7) | N7: =IF(J7=0,0,D7*10000/J7) | O7: =IF(D$13=0,0,D7/D$13) | P7: =IF(L$13=0,0,L7/L$13)
A8: 브랜드검색 | B8: ='가정'!$B$38*'가정'!$B$8/10000 | C8: =B8*'가정'!$B$7/'가정'!$B$8 | D8: =SUMIFS('데이터_광고'!$E$2:$E$500,'데이터_광고'!$A$2:$A$500,$A$4,'데이터_광고'!$B$2:$B$500,$A8)/10000 | E8: =IF(C8=0,0,D8/C8) | F8: =SUMIFS('데이터_광고'!$F$2:$F$500,'데이터_광고'!$A$2:$A$500,$A$4,'데이터_광고'!$B$2:$B$500,$A8) | G8: =SUMIFS('데이터_광고'!$G$2:$G$500,'데이터_광고'!$A$2:$A$500,$A$4,'데이터_광고'!$B$2:$B$500,$A8) | H8: =IF(F8=0,0,G8/F8) | I8: =IF(G8=0,0,D8*10000/G8) | J8: =SUMIFS('데이터_광고'!$H$2:$H$500,'데이터_광고'!$A$2:$A$500,$A$4,'데이터_광고'!$B$2:$B$500,$A8) | K8: =IF(G8=0,0,J8/G8) | L8: =SUMIFS('데이터_광고'!$I$2:$I$500,'데이터_광고'!$A$2:$A$500,$A$4,'데이터_광고'!$B$2:$B$500,$A8)/10000 | M8: =IF(D8=0,0,L8/D8) | N8: =IF(J8=0,0,D8*10000/J8) | O8: =IF(D$13=0,0,D8/D$13) | P8: =IF(L$13=0,0,L8/L$13)
A9: GFA 카탈로그 | B9: =SUMIFS('가정'!$C$16:$C$27,'가정'!$A$16:$A$27,$A$4,'가정'!$B$16:$B$27,$A9) | C9: =B9*'가정'!$B$7/'가정'!$B$8 | D9: =SUMIFS('데이터_광고'!$E$2:$E$500,'데이터_광고'!$A$2:$A$500,$A$4,'데이터_광고'!$B$2:$B$500,$A9)/10000 | E9: =IF(C9=0,0,D9/C9) | F9: =SUMIFS('데이터_광고'!$F$2:$F$500,'데이터_광고'!$A$2:$A$500,$A$4,'데이터_광고'!$B$2:$B$500,$A9) | G9: =SUMIFS('데이터_광고'!$G$2:$G$500,'데이터_광고'!$A$2:$A$500,$A$4,'데이터_광고'!$B$2:$B$500,$A9) | H9: =IF(F9=0,0,G9/F9) | I9: =IF(G9=0,0,D9*10000/G9) | J9: =SUMIFS('데이터_광고'!$H$2:$H$500,'데이터_광고'!$A$2:$A$500,$A$4,'데이터_광고'!$B$2:$B$500,$A9) | K9: =IF(G9=0,0,J9/G9) | L9: =SUMIFS('데이터_광고'!$I$2:$I$500,'데이터_광고'!$A$2:$A$500,$A$4,'데이터_광고'!$B$2:$B$500,$A9)/10000 | M9: =IF(D9=0,0,L9/D9) | N9: =IF(J9=0,0,D9*10000/J9) | O9: =IF(D$13=0,0,D9/D$13) | P9: =IF(L$13=0,0,L9/L$13)
A10: GFA 전환 | B10: =SUMIFS('가정'!$C$16:$C$27,'가정'!$A$16:$A$27,$A$4,'가정'!$B$16:$B$27,$A10) | C10: =B10*'가정'!$B$7/'가정'!$B$8 | D10: =SUMIFS('데이터_광고'!$E$2:$E$500,'데이터_광고'!$A$2:$A$500,$A$4,'데이터_광고'!$B$2:$B$500,$A10)/10000 | E10: =IF(C10=0,0,D10/C10) | F10: =SUMIFS('데이터_광고'!$F$2:$F$500,'데이터_광고'!$A$2:$A$500,$A$4,'데이터_광고'!$B$2:$B$500,$A10) | G10: =SUMIFS('데이터_광고'!$G$2:$G$500,'데이터_광고'!$A$2:$A$500,$A$4,'데이터_광고'!$B$2:$B$500,$A10) | H10: =IF(F10=0,0,G10/F10) | I10: =IF(G10=0,0,D10*10000/G10) | J10: =SUMIFS('데이터_광고'!$H$2:$H$500,'데이터_광고'!$A$2:$A$500,$A$4,'데이터_광고'!$B$2:$B$500,$A10) | K10: =IF(G10=0,0,J10/G10) | L10: =SUMIFS('데이터_광고'!$I$2:$I$500,'데이터_광고'!$A$2:$A$500,$A$4,'데이터_광고'!$B$2:$B$500,$A10)/10000 | M10: =IF(D10=0,0,L10/D10) | N10: =IF(J10=0,0,D10*10000/J10) | O10: =IF(D$13=0,0,D10/D$13) | P10: =IF(L$13=0,0,L10/L$13)
A11: 메타 스스 | B11: =SUMIFS('가정'!$C$16:$C$27,'가정'!$A$16:$A$27,$A$4,'가정'!$B$16:$B$27,$A11) | C11: =B11*'가정'!$B$7/'가정'!$B$8 | D11: =SUMIFS('데이터_광고'!$E$2:$E$500,'데이터_광고'!$A$2:$A$500,$A$4,'데이터_광고'!$B$2:$B$500,$A11)/10000 | E11: =IF(C11=0,0,D11/C11) | F11: =SUMIFS('데이터_광고'!$F$2:$F$500,'데이터_광고'!$A$2:$A$500,$A$4,'데이터_광고'!$B$2:$B$500,$A11) | G11: =SUMIFS('데이터_광고'!$G$2:$G$500,'데이터_광고'!$A$2:$A$500,$A$4,'데이터_광고'!$B$2:$B$500,$A11) | H11: =IF(F11=0,0,G11/F11) | I11: =IF(G11=0,0,D11*10000/G11) | J11: =SUMIFS('데이터_광고'!$H$2:$H$500,'데이터_광고'!$A$2:$A$500,$A$4,'데이터_광고'!$B$2:$B$500,$A11) | K11: =IF(G11=0,0,J11/G11) | L11: =SUMIFS('데이터_광고'!$I$2:$I$500,'데이터_광고'!$A$2:$A$500,$A$4,'데이터_광고'!$B$2:$B$500,$A11)/10000 | M11: =IF(D11=0,0,L11/D11) | N11: =IF(J11=0,0,D11*10000/J11) | O11: =IF(D$13=0,0,D11/D$13) | P11: =IF(L$13=0,0,L11/L$13)
A12: 메타 자사몰 | B12: =SUMIFS('가정'!$C$16:$C$27,'가정'!$A$16:$A$27,$A$4,'가정'!$B$16:$B$27,$A12) | C12: =B12*'가정'!$B$7/'가정'!$B$8 | D12: =SUMIFS('데이터_광고'!$E$2:$E$500,'데이터_광고'!$A$2:$A$500,$A$4,'데이터_광고'!$B$2:$B$500,$A12)/10000 | E12: =IF(C12=0,0,D12/C12) | F12: =SUMIFS('데이터_광고'!$F$2:$F$500,'데이터_광고'!$A$2:$A$500,$A$4,'데이터_광고'!$B$2:$B$500,$A12) | G12: =SUMIFS('데이터_광고'!$G$2:$G$500,'데이터_광고'!$A$2:$A$500,$A$4,'데이터_광고'!$B$2:$B$500,$A12) | H12: =IF(F12=0,0,G12/F12) | I12: =IF(G12=0,0,D12*10000/G12) | J12: =SUMIFS('데이터_광고'!$H$2:$H$500,'데이터_광고'!$A$2:$A$500,$A$4,'데이터_광고'!$B$2:$B$500,$A12) | K12: =IF(G12=0,0,J12/G12) | L12: =SUMIFS('데이터_광고'!$I$2:$I$500,'데이터_광고'!$A$2:$A$500,$A$4,'데이터_광고'!$B$2:$B$500,$A12)/10000 | M12: =IF(D12=0,0,L12/D12) | N12: =IF(J12=0,0,D12*10000/J12) | O12: =IF(D$13=0,0,D12/D$13) | P12: =IF(L$13=0,0,L12/L$13)
A13: 아넬라 합계 | B13: =SUM(B6:B12) | C13: =SUM(C6:C12) | D13: =SUM(D6:D12) | E13: =IF(C13=0,0,D13/C13) | F13: =SUM(F6:F12) | G13: =SUM(G6:G12) | H13: =IF(F13=0,0,G13/F13) | I13: =IF(G13=0,0,D13*10000/G13) | J13: =SUM(J6:J12) | K13: =IF(G13=0,0,J13/G13) | L13: =SUM(L6:L12) | M13: =IF(D13=0,0,L13/D13) | N13: =IF(J13=0,0,D13*10000/J13) | O13: =IF(D$13=0,0,D13/D$13) | P13: =IF(L$13=0,0,L13/L$13)
A16: 로지오가닉
A17: 매체 | B17: 10월 월예산 | C17: 일할 예산 | D17: 광고비 | E17: 일할 대비 소진율 | F17: 노출 | G17: 클릭 | H17: CTR | I17: CPC(원) | J17: 구매(건) | K17: CVR | L17: 매출 | M17: ROAS | N17: CPA(원) | O17: 광고비 비중 | P17: 매출 비중
A18: 파워링크 | B18: =SUMIFS('가정'!$C$16:$C$27,'가정'!$A$16:$A$27,$A$16,'가정'!$B$16:$B$27,$A18) | C18: =B18*'가정'!$B$7/'가정'!$B$8 | D18: =SUMIFS('데이터_광고'!$E$2:$E$500,'데이터_광고'!$A$2:$A$500,$A$16,'데이터_광고'!$B$2:$B$500,$A18)/10000 | E18: =IF(C18=0,0,D18/C18) | F18: =SUMIFS('데이터_광고'!$F$2:$F$500,'데이터_광고'!$A$2:$A$500,$A$16,'데이터_광고'!$B$2:$B$500,$A18) | G18: =SUMIFS('데이터_광고'!$G$2:$G$500,'데이터_광고'!$A$2:$A$500,$A$16,'데이터_광고'!$B$2:$B$500,$A18) | H18: =IF(F18=0,0,G18/F18) | I18: =IF(G18=0,0,D18*10000/G18) | J18: =SUMIFS('데이터_광고'!$H$2:$H$500,'데이터_광고'!$A$2:$A$500,$A$16,'데이터_광고'!$B$2:$B$500,$A18) | K18: =IF(G18=0,0,J18/G18) | L18: =SUMIFS('데이터_광고'!$I$2:$I$500,'데이터_광고'!$A$2:$A$500,$A$16,'데이터_광고'!$B$2:$B$500,$A18)/10000 | M18: =IF(D18=0,0,L18/D18) | N18: =IF(J18=0,0,D18*10000/J18) | O18: =IF(D$25=0,0,D18/D$25) | P18: =IF(L$25=0,0,L18/L$25)
A19: 쇼핑검색 | B19: =SUMIFS('가정'!$C$16:$C$27,'가정'!$A$16:$A$27,$A$16,'가정'!$B$16:$B$27,$A19) | C19: =B19*'가정'!$B$7/'가정'!$B$8 | D19: =SUMIFS('데이터_광고'!$E$2:$E$500,'데이터_광고'!$A$2:$A$500,$A$16,'데이터_광고'!$B$2:$B$500,$A19)/10000 | E19: =IF(C19=0,0,D19/C19) | F19: =SUMIFS('데이터_광고'!$F$2:$F$500,'데이터_광고'!$A$2:$A$500,$A$16,'데이터_광고'!$B$2:$B$500,$A19) | G19: =SUMIFS('데이터_광고'!$G$2:$G$500,'데이터_광고'!$A$2:$A$500,$A$16,'데이터_광고'!$B$2:$B$500,$A19) | H19: =IF(F19=0,0,G19/F19) | I19: =IF(G19=0,0,D19*10000/G19) | J19: =SUMIFS('데이터_광고'!$H$2:$H$500,'데이터_광고'!$A$2:$A$500,$A$16,'데이터_광고'!$B$2:$B$500,$A19) | K19: =IF(G19=0,0,J19/G19) | L19: =SUMIFS('데이터_광고'!$I$2:$I$500,'데이터_광고'!$A$2:$A$500,$A$16,'데이터_광고'!$B$2:$B$500,$A19)/10000 | M19: =IF(D19=0,0,L19/D19) | N19: =IF(J19=0,0,D19*10000/J19) | O19: =IF(D$25=0,0,D19/D$25) | P19: =IF(L$25=0,0,L19/L$25)
A20: 브랜드검색 | B20: ='가정'!$B$38*'가정'!$B$8/10000 | C20: =B20*'가정'!$B$7/'가정'!$B$8 | D20: =SUMIFS('데이터_광고'!$E$2:$E$500,'데이터_광고'!$A$2:$A$500,$A$16,'데이터_광고'!$B$2:$B$500,$A20)/10000 | E20: =IF(C20=0,0,D20/C20) | F20: =SUMIFS('데이터_광고'!$F$2:$F$500,'데이터_광고'!$A$2:$A$500,$A$16,'데이터_광고'!$B$2:$B$500,$A20) | G20: =SUMIFS('데이터_광고'!$G$2:$G$500,'데이터_광고'!$A$2:$A$500,$A$16,'데이터_광고'!$B$2:$B$500,$A20) | H20: =IF(F20=0,0,G20/F20) | I20: =IF(G20=0,0,D20*10000/G20) | J20: =SUMIFS('데이터_광고'!$H$2:$H$500,'데이터_광고'!$A$2:$A$500,$A$16,'데이터_광고'!$B$2:$B$500,$A20) | K20: =IF(G20=0,0,J20/G20) | L20: =SUMIFS('데이터_광고'!$I$2:$I$500,'데이터_광고'!$A$2:$A$500,$A$16,'데이터_광고'!$B$2:$B$500,$A20)/10000 | M20: =IF(D20=0,0,L20/D20) | N20: =IF(J20=0,0,D20*10000/J20) | O20: =IF(D$25=0,0,D20/D$25) | P20: =IF(L$25=0,0,L20/L$25)
A21: GFA 카탈로그 | B21: =SUMIFS('가정'!$C$16:$C$27,'가정'!$A$16:$A$27,$A$16,'가정'!$B$16:$B$27,$A21) | C21: =B21*'가정'!$B$7/'가정'!$B$8 | D21: =SUMIFS('데이터_광고'!$E$2:$E$500,'데이터_광고'!$A$2:$A$500,$A$16,'데이터_광고'!$B$2:$B$500,$A21)/10000 | E21: =IF(C21=0,0,D21/C21) | F21: =SUMIFS('데이터_광고'!$F$2:$F$500,'데이터_광고'!$A$2:$A$500,$A$16,'데이터_광고'!$B$2:$B$500,$A21) | G21: =SUMIFS('데이터_광고'!$G$2:$G$500,'데이터_광고'!$A$2:$A$500,$A$16,'데이터_광고'!$B$2:$B$500,$A21) | H21: =IF(F21=0,0,G21/F21) | I21: =IF(G21=0,0,D21*10000/G21) | J21: =SUMIFS('데이터_광고'!$H$2:$H$500,'데이터_광고'!$A$2:$A$500,$A$16,'데이터_광고'!$B$2:$B$500,$A21) | K21: =IF(G21=0,0,J21/G21) | L21: =SUMIFS('데이터_광고'!$I$2:$I$500,'데이터_광고'!$A$2:$A$500,$A$16,'데이터_광고'!$B$2:$B$500,$A21)/10000 | M21: =IF(D21=0,0,L21/D21) | N21: =IF(J21=0,0,D21*10000/J21) | O21: =IF(D$25=0,0,D21/D$25) | P21: =IF(L$25=0,0,L21/L$25)
A22: GFA 전환 | B22: =SUMIFS('가정'!$C$16:$C$27,'가정'!$A$16:$A$27,$A$16,'가정'!$B$16:$B$27,$A22) | C22: =B22*'가정'!$B$7/'가정'!$B$8 | D22: =SUMIFS('데이터_광고'!$E$2:$E$500,'데이터_광고'!$A$2:$A$500,$A$16,'데이터_광고'!$B$2:$B$500,$A22)/10000 | E22: =IF(C22=0,0,D22/C22) | F22: =SUMIFS('데이터_광고'!$F$2:$F$500,'데이터_광고'!$A$2:$A$500,$A$16,'데이터_광고'!$B$2:$B$500,$A22) | G22: =SUMIFS('데이터_광고'!$G$2:$G$500,'데이터_광고'!$A$2:$A$500,$A$16,'데이터_광고'!$B$2:$B$500,$A22) | H22: =IF(F22=0,0,G22/F22) | I22: =IF(G22=0,0,D22*10000/G22) | J22: =SUMIFS('데이터_광고'!$H$2:$H$500,'데이터_광고'!$A$2:$A$500,$A$16,'데이터_광고'!$B$2:$B$500,$A22) | K22: =IF(G22=0,0,J22/G22) | L22: =SUMIFS('데이터_광고'!$I$2:$I$500,'데이터_광고'!$A$2:$A$500,$A$16,'데이터_광고'!$B$2:$B$500,$A22)/10000 | M22: =IF(D22=0,0,L22/D22) | N22: =IF(J22=0,0,D22*10000/J22) | O22: =IF(D$25=0,0,D22/D$25) | P22: =IF(L$25=0,0,L22/L$25)
A23: 메타 스스 | B23: =SUMIFS('가정'!$C$16:$C$27,'가정'!$A$16:$A$27,$A$16,'가정'!$B$16:$B$27,$A23) | C23: =B23*'가정'!$B$7/'가정'!$B$8 | D23: =SUMIFS('데이터_광고'!$E$2:$E$500,'데이터_광고'!$A$2:$A$500,$A$16,'데이터_광고'!$B$2:$B$500,$A23)/10000 | E23: =IF(C23=0,0,D23/C23) | F23: =SUMIFS('데이터_광고'!$F$2:$F$500,'데이터_광고'!$A$2:$A$500,$A$16,'데이터_광고'!$B$2:$B$500,$A23) | G23: =SUMIFS('데이터_광고'!$G$2:$G$500,'데이터_광고'!$A$2:$A$500,$A$16,'데이터_광고'!$B$2:$B$500,$A23) | H23: =IF(F23=0,0,G23/F23) | I23: =IF(G23=0,0,D23*10000/G23) | J23: =SUMIFS('데이터_광고'!$H$2:$H$500,'데이터_광고'!$A$2:$A$500,$A$16,'데이터_광고'!$B$2:$B$500,$A23) | K23: =IF(G23=0,0,J23/G23) | L23: =SUMIFS('데이터_광고'!$I$2:$I$500,'데이터_광고'!$A$2:$A$500,$A$16,'데이터_광고'!$B$2:$B$500,$A23)/10000 | M23: =IF(D23=0,0,L23/D23) | N23: =IF(J23=0,0,D23*10000/J23) | O23: =IF(D$25=0,0,D23/D$25) | P23: =IF(L$25=0,0,L23/L$25)
A24: 메타 자사몰 | B24: =SUMIFS('가정'!$C$16:$C$27,'가정'!$A$16:$A$27,$A$16,'가정'!$B$16:$B$27,$A24) | C24: =B24*'가정'!$B$7/'가정'!$B$8 | D24: =SUMIFS('데이터_광고'!$E$2:$E$500,'데이터_광고'!$A$2:$A$500,$A$16,'데이터_광고'!$B$2:$B$500,$A24)/10000 | E24: =IF(C24=0,0,D24/C24) | F24: =SUMIFS('데이터_광고'!$F$2:$F$500,'데이터_광고'!$A$2:$A$500,$A$16,'데이터_광고'!$B$2:$B$500,$A24) | G24: =SUMIFS('데이터_광고'!$G$2:$G$500,'데이터_광고'!$A$2:$A$500,$A$16,'데이터_광고'!$B$2:$B$500,$A24) | H24: =IF(F24=0,0,G24/F24) | I24: =IF(G24=0,0,D24*10000/G24) | J24: =SUMIFS('데이터_광고'!$H$2:$H$500,'데이터_광고'!$A$2:$A$500,$A$16,'데이터_광고'!$B$2:$B$500,$A24) | K24: =IF(G24=0,0,J24/G24) | L24: =SUMIFS('데이터_광고'!$I$2:$I$500,'데이터_광고'!$A$2:$A$500,$A$16,'데이터_광고'!$B$2:$B$500,$A24)/10000 | M24: =IF(D24=0,0,L24/D24) | N24: =IF(J24=0,0,D24*10000/J24) | O24: =IF(D$25=0,0,D24/D$25) | P24: =IF(L$25=0,0,L24/L$25)
A25: 로지오가닉 합계 | B25: =SUM(B18:B24) | C25: =SUM(C18:C24) | D25: =SUM(D18:D24) | E25: =IF(C25=0,0,D25/C25) | F25: =SUM(F18:F24) | G25: =SUM(G18:G24) | H25: =IF(F25=0,0,G25/F25) | I25: =IF(G25=0,0,D25*10000/G25) | J25: =SUM(J18:J24) | K25: =IF(G25=0,0,J25/G25) | L25: =SUM(L18:L24) | M25: =IF(D25=0,0,L25/D25) | N25: =IF(J25=0,0,D25*10000/J25) | O25: =IF(D$25=0,0,D25/D$25) | P25: =IF(L$25=0,0,L25/L$25)
A27: 브랜드검색은 월 정액을 일할 안분한 값이고, 예산표(네이버 VAT 미포함)에는 포함돼 있지 않습니다. 합계 광고비·ROAS는 브랜드검색 정액을 포함한 값으로 주간·월간 리포트와 같은 기준입니다.
A29: ① 10월 목표(소급) 대비 28일 누계 실적
A30: 브랜드 | B30: 월 광고비 계획 | C30: KPI ROAS 하한 | D30: 목표 매출 (계획×하한) | E30: 28일 광고비 | F30: 28일 매출 | G30: 28일 ROAS | H30: ROAS 달성률 | I30: 판정
A31: 아넬라 | B31: =B13 | C31: ='가정'!B42 | D31: =B31*C31 | E31: =D13 | F31: =L13 | G31: =IF(E31=0,0,F31/E31) | H31: =IF(C31=0,0,G31/C31) | I31: =IF(H31>=1,"달성",IF(H31>='가정'!$B$12,"근접","미달"))
A32: 로지오가닉 | B32: =B25 | C32: ='가정'!C42 | D32: =B32*C32 | E32: =D25 | F32: =L25 | G32: =IF(E32=0,0,F32/E32) | H32: =IF(C32=0,0,G32/C32) | I32: =IF(H32>=1,"달성",IF(H32>='가정'!$B$12,"근접","미달"))
A33: 합계 | B33: =B31+B32 | C33: =IF(B33=0,0,D33/B33) | D33: =D31+D32 | E33: =E31+E32 | F33: =F31+F32 | G33: =IF(E33=0,0,F33/E33) | H33: =IF(C33=0,0,G33/C33) | I33: =IF(H33>=1,"달성",IF(H33>='가정'!$B$12,"근접","미달"))
A34: 월 광고비 계획 = 10월 예산 합계 + 브랜드검색 정액(31일분). 합계 행의 ROAS 하한은 브랜드별 목표 매출을 계획 광고비로 가중한 값입니다.
A36: ② 월말 예상 (10/29~31은 10/26~28 일평균이 이어진다고 가정)
A37: 브랜드 | B37: 월말 예상 광고비 | C37: 월말 예상 매출 | D37: 예상 ROAS | E37: 예상 ROAS 달성률 | F37: 예상 매출 ÷ 목표 매출 | G37: 예산 소진율 (예상 광고비÷계획) | H37: 월말 예상 구매(건) | I37: KPI 광고 기준 목표 주문(건) | J37: 주문 달성률 | K37: 판정 (예상 ROAS 기준)
A38: 아넬라 | B38: =E31+'주차별_추이'!F15*'가정'!$B$9/10000 | C38: =F31+'주차별_추이'!F16*'가정'!$B$9/10000 | D38: =IF(B38=0,0,C38/B38) | E38: =IF(C31=0,0,D38/C31) | F38: =IF(D31=0,0,C38/D31) | G38: =IF(B31=0,0,B38/B31) | H38: =J13+'주차별_추이'!F12/'주차별_추이'!F8*'가정'!$B$9 | I38: ='가정'!B43 | J38: =IF(I38=0,0,H38/I38) | K38: =IF(E38>=1,"달성",IF(E38>='가정'!$B$12,"근접","미달"))
A39: 로지오가닉 | B39: =E32+'주차별_추이'!F36*'가정'!$B$9/10000 | C39: =F32+'주차별_추이'!F37*'가정'!$B$9/10000 | D39: =IF(B39=0,0,C39/B39) | E39: =IF(C32=0,0,D39/C32) | F39: =IF(D32=0,0,C39/D32) | G39: =IF(B32=0,0,B39/B32) | H39: =J25+'주차별_추이'!F33/'주차별_추이'!F29*'가정'!$B$9 | I39: ='가정'!C43 | J39: =IF(I39=0,0,H39/I39) | K39: =IF(E39>=1,"달성",IF(E39>='가정'!$B$12,"근접","미달"))
A40: 합계 | B40: =B38+B39 | C40: =C38+C39 | D40: =IF(B40=0,0,C40/B40) | E40: =IF(C33=0,0,D40/C33) | F40: =IF(D33=0,0,C40/D33) | G40: =IF(B33=0,0,B40/B33) | H40: =H38+H39 | I40: =I38+I39 | J40: =IF(I40=0,0,H40/I40) | K40: =IF(E40>=1,"달성",IF(E40>='가정'!$B$12,"근접","미달"))
A41: 월말 예상 광고비·매출 = 28일 누계 + 10/26~28 일평균 × 잔여일수. 10/26~28이 넾다세일 구간이라 상시 구간보다 높게 잡힐 수 있습니다. KPI 목표 주문은 4분기 KPI 보고안의 월 환산값입니다.
A43: ③ 로지오가닉 메타 스스 이상치(10/24~25) 제외 시 (점검 시트 참조)
A44: 구분 | B44: 28일 광고비 | C44: 28일 매출 | D44: 28일 ROAS | E44: KPI 하한 대비
A45: 원본 | B45: =E32 | C45: =F32 | D45: =IF(B45=0,0,C45/B45) | E45: =IF(C32=0,0,D45/C32)
A46: 보정 (이상치 이틀 제외) | B46: =E32-'점검'!D14/10000 | C46: =F32-'점검'!E14/10000 | D46: =IF(B46=0,0,C46/B46) | E46: =IF(C32=0,0,D46/C32)

Sheet 예산
A1: 10월·11월 광고 예산 (만원, 네이버 VAT 미포함)
A2: 예산은 가정 시트의 입력값을 참조합니다. 12월은 11월 유지 가정입니다. 10월 집행은 10/1~10/28(28일) 광고비이고, 일할 대비 소진율은 10월 예산을 28/31로 환산한 값 대비입니다.
A4: 아넬라
A5: 매체 | B5: 10월 예산 | C5: 11월 예산 | D5: 증감 | E5: 증감률 | F5: 12월 (11월 유지) | G5: 10월 집행 (28일) | H5: 일할 대비 소진율 | I5: 변경 사유 · 운영 메모
A6: 파워링크 | B6: =SUMIFS('가정'!$C$16:$C$27,'가정'!$A$16:$A$27,$A$4,'가정'!$B$16:$B$27,$A6) | C6: =SUMIFS('가정'!$D$16:$D$27,'가정'!$A$16:$A$27,$A$4,'가정'!$B$16:$B$27,$A6) | D6: =C6-B6 | E6: =IF(B6=0,0,C6/B6-1) | F6: =SUMIFS('가정'!$E$16:$E$27,'가정'!$A$16:$A$27,$A$4,'가정'!$B$16:$B$27,$A6) | G6: ='10월_실적'!D6 | H6: =IF(B6=0,0,G6/(B6*'가정'!$B$7/'가정'!$B$8)) | I6: 변동 없음. 10/14 노출 시간 제한 유지(노출 제외 0~3시, 17~24시), 10/21 저효율 키워드 일예산 감액.
A7: 쇼핑검색 | B7: =SUMIFS('가정'!$C$16:$C$27,'가정'!$A$16:$A$27,$A$4,'가정'!$B$16:$B$27,$A7) | C7: =SUMIFS('가정'!$D$16:$D$27,'가정'!$A$16:$A$27,$A$4,'가정'!$B$16:$B$27,$A7) | D7: =C7-B7 | E7: =IF(B7=0,0,C7/B7-1) | F7: =SUMIFS('가정'!$E$16:$E$27,'가정'!$A$16:$A$27,$A$4,'가정'!$B$16:$B$27,$A7) | G7: ='10월_실적'!D7 | H7: =IF(B7=0,0,G7/(B7*'가정'!$B$7/'가정'!$B$8)) | I7: 변동 없음. 10/26 넾다세일부터 24시간 균등 노출로 원복.
A8: GFA 카탈로그 | B8: =SUMIFS('가정'!$C$16:$C$27,'가정'!$A$16:$A$27,$A$4,'가정'!$B$16:$B$27,$A8) | C8: =SUMIFS('가정'!$D$16:$D$27,'가정'!$A$16:$A$27,$A$4,'가정'!$B$16:$B$27,$A8) | D8: =C8-B8 | E8: =IF(B8=0,0,C8/B8-1) | F8: =SUMIFS('가정'!$E$16:$E$27,'가정'!$A$16:$A$27,$A$4,'가정'!$B$16:$B$27,$A8) | G8: ='10월_실적'!D9 | H8: =IF(B8=0,0,G8/(B8*'가정'!$B$7/'가정'!$B$8)) | I8: 변동 없음.
A9: GFA 전환 | B9: =SUMIFS('가정'!$C$16:$C$27,'가정'!$A$16:$A$27,$A$4,'가정'!$B$16:$B$27,$A9) | C9: =SUMIFS('가정'!$D$16:$D$27,'가정'!$A$16:$A$27,$A$4,'가정'!$B$16:$B$27,$A9) | D9: =C9-B9 | E9: =IF(B9=0,0,C9/B9-1) | F9: =SUMIFS('가정'!$E$16:$E$27,'가정'!$A$16:$A$27,$A$4,'가정'!$B$16:$B$27,$A9) | G9: ='10월_실적'!D10 | H9: =IF(B9=0,0,G9/(B9*'가정'!$B$7/'가정'!$B$8)) | I9: 250만원에서 150만원으로 감액. 신규 소구점 5종 테스트가 소재 검토로 HOLD 중.
A10: 메타 스스 | B10: =SUMIFS('가정'!$C$16:$C$27,'가정'!$A$16:$A$27,$A$4,'가정'!$B$16:$B$27,$A10) | C10: =SUMIFS('가정'!$D$16:$D$27,'가정'!$A$16:$A$27,$A$4,'가정'!$B$16:$B$27,$A10) | D10: =C10-B10 | E10: =IF(B10=0,0,C10/B10-1) | F10: =SUMIFS('가정'!$E$16:$E$27,'가정'!$A$16:$A$27,$A$4,'가정'!$B$16:$B$27,$A10) | G10: ='10월_실적'!D11 | H10: =IF(B10=0,0,G10/(B10*'가정'!$B$7/'가정'!$B$8)) | I10: 변동 없음. 넾다세일부터 인스타그램 지면 고정, 광고 상품은 영업팀 주력 상품으로 전환.
A11: 메타 자사몰 | B11: =SUMIFS('가정'!$C$16:$C$27,'가정'!$A$16:$A$27,$A$4,'가정'!$B$16:$B$27,$A11) | C11: =SUMIFS('가정'!$D$16:$D$27,'가정'!$A$16:$A$27,$A$4,'가정'!$B$16:$B$27,$A11) | D11: =C11-B11 | E11: =IF(B11=0,0,C11/B11-1) | F11: =SUMIFS('가정'!$E$16:$E$27,'가정'!$A$16:$A$27,$A$4,'가정'!$B$16:$B$27,$A11) | G11: ='10월_실적'!D12 | H11: =IF(B11=0,0,G11/(B11*'가정'!$B$7/'가정'!$B$8)) | I11: 250만원에서 180만원으로 축소. 웰컴박스·기획전 보류.
A12: 아넬라 합계 | B12: =SUM(B6:B11) | C12: =SUM(C6:C11) | D12: =C12-B12 | E12: =IF(B12=0,0,C12/B12-1) | F12: =SUM(F6:F11) | G12: =SUM(G6:G11) | H12: =IF(B12=0,0,G12/(B12*'가정'!$B$7/'가정'!$B$8))
A13: (참고) 브랜드검색 정액 | B13: ='가정'!$B$38*'가정'!$B$8/10000 | C13: ='가정'!$B$38*'가정'!$B$10/10000 | D13: =C13-B13 | F13: ='가정'!$B$38*'가정'!$B$11/10000 | G13: ='10월_실적'!D8 | I13: 예산표에는 포함되지 않는 정액 상품입니다(월 88만원을 일수로 안분).
A15: 로지오가닉
A16: 매체 | B16: 10월 예산 | C16: 11월 예산 | D16: 증감 | E16: 증감률 | F16: 12월 (11월 유지) | G16: 10월 집행 (28일) | H16: 일할 대비 소진율 | I16: 변경 사유 · 운영 메모
A17: 파워링크 | B17: =SUMIFS('가정'!$C$16:$C$27,'가정'!$A$16:$A$27,$A$15,'가정'!$B$16:$B$27,$A17) | C17: =SUMIFS('가정'!$D$16:$D$27,'가정'!$A$16:$A$27,$A$15,'가정'!$B$16:$B$27,$A17) | D17: =C17-B17 | E17: =IF(B17=0,0,C17/B17-1) | F17: =SUMIFS('가정'!$E$16:$E$27,'가정'!$A$16:$A$27,$A$15,'가정'!$B$16:$B$27,$A17) | G17: ='10월_실적'!D18 | H17: =IF(B17=0,0,G17/(B17*'가정'!$B$7/'가정'!$B$8)) | I17: 변동 없음. 10/21 저효율 키워드 일예산 감액.
A18: 쇼핑검색 | B18: =SUMIFS('가정'!$C$16:$C$27,'가정'!$A$16:$A$27,$A$15,'가정'!$B$16:$B$27,$A18) | C18: =SUMIFS('가정'!$D$16:$D$27,'가정'!$A$16:$A$27,$A$15,'가정'!$B$16:$B$27,$A18) | D18: =C18-B18 | E18: =IF(B18=0,0,C18/B18-1) | F18: =SUMIFS('가정'!$E$16:$E$27,'가정'!$A$16:$A$27,$A$15,'가정'!$B$16:$B$27,$A18) | G18: ='10월_실적'!D19 | H18: =IF(B18=0,0,G18/(B18*'가정'!$B$7/'가정'!$B$8)) | I18: 변동 없음. 10/26 무전환 지면 노출 제외.
A19: GFA 카탈로그 | B19: =SUMIFS('가정'!$C$16:$C$27,'가정'!$A$16:$A$27,$A$15,'가정'!$B$16:$B$27,$A19) | C19: =SUMIFS('가정'!$D$16:$D$27,'가정'!$A$16:$A$27,$A$15,'가정'!$B$16:$B$27,$A19) | D19: =C19-B19 | E19: =IF(B19=0,0,C19/B19-1) | F19: =SUMIFS('가정'!$E$16:$E$27,'가정'!$A$16:$A$27,$A$15,'가정'!$B$16:$B$27,$A19) | G19: ='10월_실적'!D21 | H19: =IF(B19=0,0,G19/(B19*'가정'!$B$7/'가정'!$B$8)) | I19: 변동 없음.
A20: GFA 전환 | B20: =SUMIFS('가정'!$C$16:$C$27,'가정'!$A$16:$A$27,$A$15,'가정'!$B$16:$B$27,$A20) | C20: =SUMIFS('가정'!$D$16:$D$27,'가정'!$A$16:$A$27,$A$15,'가정'!$B$16:$B$27,$A20) | D20: =C20-B20 | E20: =IF(B20=0,0,C20/B20-1) | F20: =SUMIFS('가정'!$E$16:$E$27,'가정'!$A$16:$A$27,$A$15,'가정'!$B$16:$B$27,$A20) | G20: ='10월_실적'!D22 | H20: =IF(B20=0,0,G20/(B20*'가정'!$B$7/'가정'!$B$8)) | I20: 11월 신설 20만원, 넾다세일 한정. 12월은 11월 유지 가정이라 같은 값이 들어가 있어 사용처 확정 필요.
A21: 메타 스스 | B21: =SUMIFS('가정'!$C$16:$C$27,'가정'!$A$16:$A$27,$A$15,'가정'!$B$16:$B$27,$A21) | C21: =SUMIFS('가정'!$D$16:$D$27,'가정'!$A$16:$A$27,$A$15,'가정'!$B$16:$B$27,$A21) | D21: =C21-B21 | E21: =IF(B21=0,0,C21/B21-1) | F21: =SUMIFS('가정'!$E$16:$E$27,'가정'!$A$16:$A$27,$A$15,'가정'!$B$16:$B$27,$A21) | G21: ='10월_실적'!D23 | H21: =IF(B21=0,0,G21/(B21*'가정'!$B$7/'가정'!$B$8)) | I21: 250만원에서 215만원으로 약간 감액. 넾다세일 영향.
A22: 메타 자사몰 | B22: =SUMIFS('가정'!$C$16:$C$27,'가정'!$A$16:$A$27,$A$15,'가정'!$B$16:$B$27,$A22) | C22: =SUMIFS('가정'!$D$16:$D$27,'가정'!$A$16:$A$27,$A$15,'가정'!$B$16:$B$27,$A22) | D22: =C22-B22 | E22: =IF(B22=0,0,C22/B22-1) | F22: =SUMIFS('가정'!$E$16:$E$27,'가정'!$A$16:$A$27,$A$15,'가정'!$B$16:$B$27,$A22) | G22: ='10월_실적'!D24 | H22: =IF(B22=0,0,G22/(B22*'가정'!$B$7/'가정'!$B$8)) | I22: 180만원에서 150만원으로 감액. 보리차 시크릿링크 보류.
A23: 로지오가닉 합계 | B23: =SUM(B17:B22) | C23: =SUM(C17:C22) | D23: =C23-B23 | E23: =IF(B23=0,0,C23/B23-1) | F23: =SUM(F17:F22) | G23: =SUM(G17:G22) | H23: =IF(B23=0,0,G23/(B23*'가정'!$B$7/'가정'!$B$8))
A24: (참고) 브랜드검색 정액 | B24: ='가정'!$B$38*'가정'!$B$8/10000 | C24: ='가정'!$B$38*'가정'!$B$10/10000 | D24: =C24-B24 | F24: ='가정'!$B$38*'가정'!$B$11/10000 | G24: ='10월_실적'!D20 | I24: 예산표에는 포함되지 않는 정액 상품입니다(월 88만원을 일수로 안분).
A26: 전체 합계 | B26: =B12+B23 | C26: =C12+C23 | D26: =C26-B26 | E26: =IF(B26=0,0,C26/B26-1) | F26: =F12+F23 | G26: =G12+G23 | H26: =IF(B26=0,0,G26/(B26*'가정'!$B$7/'가정'!$B$8))
A27: 검증: 제시 합계와 차이(0이면 일치) | B27: ='가정'!C34 | C27: ='가정'!D34
A29: 4분기 KPI 보고안 광고예산과 비교 (브랜드검색 정액 포함 기준)
A30: 브랜드 | B30: KPI안 10월 | C30: 실행 10월 | D30: 차이 | F30: KPI안 11월 | G30: 실행 11월 | H30: 차이 | I30: KPI안 12월 / 실행 12월 / 차이
A31: 아넬라 | B31: ='가정'!B44 | C31: =B12+B13 | D31: =C31-B31 | F31: ='가정'!B45 | G31: =C12+C13 | H31: =G31-F31 | I31: =TEXT('가정'!B46,"#,##0")&" / "&TEXT(F12+F13,"#,##0.0")&" / "&TEXT(F12+F13-'가정'!B46,"+#,##0.0;-#,##0.0;0.0")
A32: 로지오가닉 | B32: ='가정'!C44 | C32: =B23+B24 | D32: =C32-B32 | F32: ='가정'!C45 | G32: =C23+C24 | H32: =G32-F32 | I32: =TEXT('가정'!C46,"#,##0")&" / "&TEXT(F23+F24,"#,##0.0")&" / "&TEXT(F23+F24-'가정'!C46,"+#,##0.0;-#,##0.0;0.0")
A33: KPI안의 10월 예산(1,300 / 900)은 실행 예산에 브랜드검색 정액을 더한 값과 거의 일치합니다. 아넬라 11~12월은 KPI안보다 낮고, 로지오가닉은 KPI안보다 높게 편성돼 있습니다.
A35: 운영 메모 (사용자 전달 사항)
A36: · 넾다세일(10/26~11/8, 아넬라·로지 모두)부터 메타는 인스타그램 지면만 고정으로 운영합니다.
A37: · 10월 중순부터 효율이 낮은 키워드·지면은 OFF 또는 감액 중입니다.
A38: · 넾다세일부터 메타 광고 상품은 상시 상품(아넬라 퓨레 6+6, 로지 쌀과자 8봉)이 아니라 영업팀 주력 상품으로 운영합니다.
A39: · 12월 예산은 11월 예산을 유지하는 것으로 보고 있습니다. 블랙프라이데이 등 행사 일정이 정해지면 조정합니다.

Sheet 예산대비_집행
A1: 10월 예산 대비 집행 광고비·매출 (매체별)
A2: 금액은 만원(네이버 VAT 미포함). 집행·매출은 10/1~10/28(28일) 실적이고, 월말 예상은 28일 누계에 10/26~28 일평균 × 잔여일수를 더한 값입니다. 매출은 매체가 보고한 구매 귀속 매출입니다.
A3: 소진 판정 기준 (입력) | B3: 1.05 | C3: 초과 이상 | D3: 0.8 | E3: 미소진 미만 (월말 예상 소진율 기준)
A5: 아넬라
A6: 매체 | B6: 월 예산 | C6: 일할 예산 (28일) | D6: 집행 광고비 | E6: 일할 대비 소진율 | F6: 월 예산 대비 소진율 | G6: 잔여 예산 | H6: 월말 예상 광고비 | I6: 월말 예상 소진율 | J6: 구매 (건) | K6: 매출 | L6: ROAS | M6: 월말 예상 매출 | N6: 예상 매출 ÷ 월 예산 | O6: 소진 판정
A7: 파워링크 | B7: =SUMIFS('가정'!$C$16:$C$27,'가정'!$A$16:$A$27,$A$5,'가정'!$B$16:$B$27,$A7) | C7: =B7*'가정'!$B$7/'가정'!$B$8 | D7: =SUMIFS('데이터_광고'!$E$2:$E$500,'데이터_광고'!$A$2:$A$500,$A$5,'데이터_광고'!$B$2:$B$500,$A7)/10000 | E7: =IF(C7=0,0,D7/C7) | F7: =IF(B7=0,0,D7/B7) | G7: =B7-D7 | H7: =D7+SUMIFS('데이터_광고'!$E$2:$E$500,'데이터_광고'!$A$2:$A$500,$A$5,'데이터_광고'!$B$2:$B$500,$A7,'데이터_광고'!$D$2:$D$500,'가정'!$A$54)/10000/'가정'!$D$54*'가정'!$B$9 | I7: =IF(B7=0,0,H7/B7) | J7: =SUMIFS('데이터_광고'!$H$2:$H$500,'데이터_광고'!$A$2:$A$500,$A$5,'데이터_광고'!$B$2:$B$500,$A7) | K7: =SUMIFS('데이터_광고'!$I$2:$I$500,'데이터_광고'!$A$2:$A$500,$A$5,'데이터_광고'!$B$2:$B$500,$A7)/10000 | L7: =IF(D7=0,0,K7/D7) | M7: =K7+SUMIFS('데이터_광고'!$I$2:$I$500,'데이터_광고'!$A$2:$A$500,$A$5,'데이터_광고'!$B$2:$B$500,$A7,'데이터_광고'!$D$2:$D$500,'가정'!$A$54)/10000/'가정'!$D$54*'가정'!$B$9 | N7: =IF(B7=0,0,M7/B7) | O7: =IF(B7=0,"예산 없음",IF(I7>=$B$3,"초과",IF(I7<$D$3,"미소진","적정")))
A8: 쇼핑검색 | B8: =SUMIFS('가정'!$C$16:$C$27,'가정'!$A$16:$A$27,$A$5,'가정'!$B$16:$B$27,$A8) | C8: =B8*'가정'!$B$7/'가정'!$B$8 | D8: =SUMIFS('데이터_광고'!$E$2:$E$500,'데이터_광고'!$A$2:$A$500,$A$5,'데이터_광고'!$B$2:$B$500,$A8)/10000 | E8: =IF(C8=0,0,D8/C8) | F8: =IF(B8=0,0,D8/B8) | G8: =B8-D8 | H8: =D8+SUMIFS('데이터_광고'!$E$2:$E$500,'데이터_광고'!$A$2:$A$500,$A$5,'데이터_광고'!$B$2:$B$500,$A8,'데이터_광고'!$D$2:$D$500,'가정'!$A$54)/10000/'가정'!$D$54*'가정'!$B$9 | I8: =IF(B8=0,0,H8/B8) | J8: =SUMIFS('데이터_광고'!$H$2:$H$500,'데이터_광고'!$A$2:$A$500,$A$5,'데이터_광고'!$B$2:$B$500,$A8) | K8: =SUMIFS('데이터_광고'!$I$2:$I$500,'데이터_광고'!$A$2:$A$500,$A$5,'데이터_광고'!$B$2:$B$500,$A8)/10000 | L8: =IF(D8=0,0,K8/D8) | M8: =K8+SUMIFS('데이터_광고'!$I$2:$I$500,'데이터_광고'!$A$2:$A$500,$A$5,'데이터_광고'!$B$2:$B$500,$A8,'데이터_광고'!$D$2:$D$500,'가정'!$A$54)/10000/'가정'!$D$54*'가정'!$B$9 | N8: =IF(B8=0,0,M8/B8) | O8: =IF(B8=0,"예산 없음",IF(I8>=$B$3,"초과",IF(I8<$D$3,"미소진","적정")))
A9: GFA 카탈로그 | B9: =SUMIFS('가정'!$C$16:$C$27,'가정'!$A$16:$A$27,$A$5,'가정'!$B$16:$B$27,$A9) | C9: =B9*'가정'!$B$7/'가정'!$B$8 | D9: =SUMIFS('데이터_광고'!$E$2:$E$500,'데이터_광고'!$A$2:$A$500,$A$5,'데이터_광고'!$B$2:$B$500,$A9)/10000 | E9: =IF(C9=0,0,D9/C9) | F9: =IF(B9=0,0,D9/B9) | G9: =B9-D9 | H9: =D9+SUMIFS('데이터_광고'!$E$2:$E$500,'데이터_광고'!$A$2:$A$500,$A$5,'데이터_광고'!$B$2:$B$500,$A9,'데이터_광고'!$D$2:$D$500,'가정'!$A$54)/10000/'가정'!$D$54*'가정'!$B$9 | I9: =IF(B9=0,0,H9/B9) | J9: =SUMIFS('데이터_광고'!$H$2:$H$500,'데이터_광고'!$A$2:$A$500,$A$5,'데이터_광고'!$B$2:$B$500,$A9) | K9: =SUMIFS('데이터_광고'!$I$2:$I$500,'데이터_광고'!$A$2:$A$500,$A$5,'데이터_광고'!$B$2:$B$500,$A9)/10000 | L9: =IF(D9=0,0,K9/D9) | M9: =K9+SUMIFS('데이터_광고'!$I$2:$I$500,'데이터_광고'!$A$2:$A$500,$A$5,'데이터_광고'!$B$2:$B$500,$A9,'데이터_광고'!$D$2:$D$500,'가정'!$A$54)/10000/'가정'!$D$54*'가정'!$B$9 | N9: =IF(B9=0,0,M9/B9) | O9: =IF(B9=0,"예산 없음",IF(I9>=$B$3,"초과",IF(I9<$D$3,"미소진","적정")))
A10: GFA 전환 | B10: =SUMIFS('가정'!$C$16:$C$27,'가정'!$A$16:$A$27,$A$5,'가정'!$B$16:$B$27,$A10) | C10: =B10*'가정'!$B$7/'가정'!$B$8 | D10: =SUMIFS('데이터_광고'!$E$2:$E$500,'데이터_광고'!$A$2:$A$500,$A$5,'데이터_광고'!$B$2:$B$500,$A10)/10000 | E10: =IF(C10=0,0,D10/C10) | F10: =IF(B10=0,0,D10/B10) | G10: =B10-D10 | H10: =D10+SUMIFS('데이터_광고'!$E$2:$E$500,'데이터_광고'!$A$2:$A$500,$A$5,'데이터_광고'!$B$2:$B$500,$A10,'데이터_광고'!$D$2:$D$500,'가정'!$A$54)/10000/'가정'!$D$54*'가정'!$B$9 | I10: =IF(B10=0,0,H10/B10) | J10: =SUMIFS('데이터_광고'!$H$2:$H$500,'데이터_광고'!$A$2:$A$500,$A$5,'데이터_광고'!$B$2:$B$500,$A10) | K10: =SUMIFS('데이터_광고'!$I$2:$I$500,'데이터_광고'!$A$2:$A$500,$A$5,'데이터_광고'!$B$2:$B$500,$A10)/10000 | L10: =IF(D10=0,0,K10/D10) | M10: =K10+SUMIFS('데이터_광고'!$I$2:$I$500,'데이터_광고'!$A$2:$A$500,$A$5,'데이터_광고'!$B$2:$B$500,$A10,'데이터_광고'!$D$2:$D$500,'가정'!$A$54)/10000/'가정'!$D$54*'가정'!$B$9 | N10: =IF(B10=0,0,M10/B10) | O10: =IF(B10=0,"예산 없음",IF(I10>=$B$3,"초과",IF(I10<$D$3,"미소진","적정")))
A11: 메타 스스 | B11: =SUMIFS('가정'!$C$16:$C$27,'가정'!$A$16:$A$27,$A$5,'가정'!$B$16:$B$27,$A11) | C11: =B11*'가정'!$B$7/'가정'!$B$8 | D11: =SUMIFS('데이터_광고'!$E$2:$E$500,'데이터_광고'!$A$2:$A$500,$A$5,'데이터_광고'!$B$2:$B$500,$A11)/10000 | E11: =IF(C11=0,0,D11/C11) | F11: =IF(B11=0,0,D11/B11) | G11: =B11-D11 | H11: =D11+SUMIFS('데이터_광고'!$E$2:$E$500,'데이터_광고'!$A$2:$A$500,$A$5,'데이터_광고'!$B$2:$B$500,$A11,'데이터_광고'!$D$2:$D$500,'가정'!$A$54)/10000/'가정'!$D$54*'가정'!$B$9 | I11: =IF(B11=0,0,H11/B11) | J11: =SUMIFS('데이터_광고'!$H$2:$H$500,'데이터_광고'!$A$2:$A$500,$A$5,'데이터_광고'!$B$2:$B$500,$A11) | K11: =SUMIFS('데이터_광고'!$I$2:$I$500,'데이터_광고'!$A$2:$A$500,$A$5,'데이터_광고'!$B$2:$B$500,$A11)/10000 | L11: =IF(D11=0,0,K11/D11) | M11: =K11+SUMIFS('데이터_광고'!$I$2:$I$500,'데이터_광고'!$A$2:$A$500,$A$5,'데이터_광고'!$B$2:$B$500,$A11,'데이터_광고'!$D$2:$D$500,'가정'!$A$54)/10000/'가정'!$D$54*'가정'!$B$9 | N11: =IF(B11=0,0,M11/B11) | O11: =IF(B11=0,"예산 없음",IF(I11>=$B$3,"초과",IF(I11<$D$3,"미소진","적정")))
A12: 메타 자사몰 | B12: =SUMIFS('가정'!$C$16:$C$27,'가정'!$A$16:$A$27,$A$5,'가정'!$B$16:$B$27,$A12) | C12: =B12*'가정'!$B$7/'가정'!$B$8 | D12: =SUMIFS('데이터_광고'!$E$2:$E$500,'데이터_광고'!$A$2:$A$500,$A$5,'데이터_광고'!$B$2:$B$500,$A12)/10000 | E12: =IF(C12=0,0,D12/C12) | F12: =IF(B12=0,0,D12/B12) | G12: =B12-D12 | H12: =D12+SUMIFS('데이터_광고'!$E$2:$E$500,'데이터_광고'!$A$2:$A$500,$A$5,'데이터_광고'!$B$2:$B$500,$A12,'데이터_광고'!$D$2:$D$500,'가정'!$A$54)/10000/'가정'!$D$54*'가정'!$B$9 | I12: =IF(B12=0,0,H12/B12) | J12: =SUMIFS('데이터_광고'!$H$2:$H$500,'데이터_광고'!$A$2:$A$500,$A$5,'데이터_광고'!$B$2:$B$500,$A12) | K12: =SUMIFS('데이터_광고'!$I$2:$I$500,'데이터_광고'!$A$2:$A$500,$A$5,'데이터_광고'!$B$2:$B$500,$A12)/10000 | L12: =IF(D12=0,0,K12/D12) | M12: =K12+SUMIFS('데이터_광고'!$I$2:$I$500,'데이터_광고'!$A$2:$A$500,$A$5,'데이터_광고'!$B$2:$B$500,$A12,'데이터_광고'!$D$2:$D$500,'가정'!$A$54)/10000/'가정'!$D$54*'가정'!$B$9 | N12: =IF(B12=0,0,M12/B12) | O12: =IF(B12=0,"예산 없음",IF(I12>=$B$3,"초과",IF(I12<$D$3,"미소진","적정")))
A13: 브랜드검색 (정액, 예산표 외) | B13: ='가정'!$B$38*'가정'!$B$8/10000 | C13: =B13*'가정'!$B$7/'가정'!$B$8 | D13: =SUMIFS('데이터_광고'!$E$2:$E$500,'데이터_광고'!$A$2:$A$500,$A$5,'데이터_광고'!$B$2:$B$500,"브랜드검색")/10000 | E13: =IF(C13=0,0,D13/C13) | F13: =IF(B13=0,0,D13/B13) | G13: =B13-D13 | H13: =D13+SUMIFS('데이터_광고'!$E$2:$E$500,'데이터_광고'!$A$2:$A$500,$A$5,'데이터_광고'!$B$2:$B$500,"브랜드검색",'데이터_광고'!$D$2:$D$500,'가정'!$A$54)/10000/'가정'!$D$54*'가정'!$B$9 | I13: =IF(B13=0,0,H13/B13) | J13: =SUMIFS('데이터_광고'!$H$2:$H$500,'데이터_광고'!$A$2:$A$500,$A$5,'데이터_광고'!$B$2:$B$500,"브랜드검색") | K13: =SUMIFS('데이터_광고'!$I$2:$I$500,'데이터_광고'!$A$2:$A$500,$A$5,'데이터_광고'!$B$2:$B$500,"브랜드검색")/10000 | L13: =IF(D13=0,0,K13/D13) | M13: =K13+SUMIFS('데이터_광고'!$I$2:$I$500,'데이터_광고'!$A$2:$A$500,$A$5,'데이터_광고'!$B$2:$B$500,"브랜드검색",'데이터_광고'!$D$2:$D$500,'가정'!$A$54)/10000/'가정'!$D$54*'가정'!$B$9 | N13: =IF(B13=0,0,M13/B13) | O13: =IF(B13=0,"예산 없음",IF(I13>=$B$3,"초과",IF(I13<$D$3,"미소진","적정")))
A14: 아넬라 합계 (예산표 기준, 브랜드검색 제외) | B14: =SUM(B7:B12) | C14: =B14*'가정'!$B$7/'가정'!$B$8 | D14: =SUM(D7:D12) | E14: =IF(C14=0,0,D14/C14) | F14: =IF(B14=0,0,D14/B14) | G14: =B14-D14 | H14: =SUM(H7:H12) | I14: =IF(B14=0,0,H14/B14) | J14: =SUM(J7:J12) | K14: =SUM(K7:K12) | L14: =IF(D14=0,0,K14/D14) | M14: =SUM(M7:M12) | N14: =IF(B14=0,0,M14/B14) | O14: =IF(B14=0,"예산 없음",IF(I14>=$B$3,"초과",IF(I14<$D$3,"미소진","적정")))
A15: 아넬라 합계 (브랜드검색 포함) | B15: =B14+B13 | C15: =B15*'가정'!$B$7/'가정'!$B$8 | D15: =D14+D13 | E15: =IF(C15=0,0,D15/C15) | F15: =IF(B15=0,0,D15/B15) | G15: =B15-D15 | H15: =H14+H13 | I15: =IF(B15=0,0,H15/B15) | J15: =J14+J13 | K15: =K14+K13 | L15: =IF(D15=0,0,K15/D15) | M15: =M14+M13 | N15: =IF(B15=0,0,M15/B15) | O15: =IF(B15=0,"예산 없음",IF(I15>=$B$3,"초과",IF(I15<$D$3,"미소진","적정")))
A17: 로지오가닉
A18: 매체 | B18: 월 예산 | C18: 일할 예산 (28일) | D18: 집행 광고비 | E18: 일할 대비 소진율 | F18: 월 예산 대비 소진율 | G18: 잔여 예산 | H18: 월말 예상 광고비 | I18: 월말 예상 소진율 | J18: 구매 (건) | K18: 매출 | L18: ROAS | M18: 월말 예상 매출 | N18: 예상 매출 ÷ 월 예산 | O18: 소진 판정
A19: 파워링크 | B19: =SUMIFS('가정'!$C$16:$C$27,'가정'!$A$16:$A$27,$A$17,'가정'!$B$16:$B$27,$A19) | C19: =B19*'가정'!$B$7/'가정'!$B$8 | D19: =SUMIFS('데이터_광고'!$E$2:$E$500,'데이터_광고'!$A$2:$A$500,$A$17,'데이터_광고'!$B$2:$B$500,$A19)/10000 | E19: =IF(C19=0,0,D19/C19) | F19: =IF(B19=0,0,D19/B19) | G19: =B19-D19 | H19: =D19+SUMIFS('데이터_광고'!$E$2:$E$500,'데이터_광고'!$A$2:$A$500,$A$17,'데이터_광고'!$B$2:$B$500,$A19,'데이터_광고'!$D$2:$D$500,'가정'!$A$54)/10000/'가정'!$D$54*'가정'!$B$9 | I19: =IF(B19=0,0,H19/B19) | J19: =SUMIFS('데이터_광고'!$H$2:$H$500,'데이터_광고'!$A$2:$A$500,$A$17,'데이터_광고'!$B$2:$B$500,$A19) | K19: =SUMIFS('데이터_광고'!$I$2:$I$500,'데이터_광고'!$A$2:$A$500,$A$17,'데이터_광고'!$B$2:$B$500,$A19)/10000 | L19: =IF(D19=0,0,K19/D19) | M19: =K19+SUMIFS('데이터_광고'!$I$2:$I$500,'데이터_광고'!$A$2:$A$500,$A$17,'데이터_광고'!$B$2:$B$500,$A19,'데이터_광고'!$D$2:$D$500,'가정'!$A$54)/10000/'가정'!$D$54*'가정'!$B$9 | N19: =IF(B19=0,0,M19/B19) | O19: =IF(B19=0,"예산 없음",IF(I19>=$B$3,"초과",IF(I19<$D$3,"미소진","적정")))
A20: 쇼핑검색 | B20: =SUMIFS('가정'!$C$16:$C$27,'가정'!$A$16:$A$27,$A$17,'가정'!$B$16:$B$27,$A20) | C20: =B20*'가정'!$B$7/'가정'!$B$8 | D20: =SUMIFS('데이터_광고'!$E$2:$E$500,'데이터_광고'!$A$2:$A$500,$A$17,'데이터_광고'!$B$2:$B$500,$A20)/10000 | E20: =IF(C20=0,0,D20/C20) | F20: =IF(B20=0,0,D20/B20) | G20: =B20-D20 | H20: =D20+SUMIFS('데이터_광고'!$E$2:$E$500,'데이터_광고'!$A$2:$A$500,$A$17,'데이터_광고'!$B$2:$B$500,$A20,'데이터_광고'!$D$2:$D$500,'가정'!$A$54)/10000/'가정'!$D$54*'가정'!$B$9 | I20: =IF(B20=0,0,H20/B20) | J20: =SUMIFS('데이터_광고'!$H$2:$H$500,'데이터_광고'!$A$2:$A$500,$A$17,'데이터_광고'!$B$2:$B$500,$A20) | K20: =SUMIFS('데이터_광고'!$I$2:$I$500,'데이터_광고'!$A$2:$A$500,$A$17,'데이터_광고'!$B$2:$B$500,$A20)/10000 | L20: =IF(D20=0,0,K20/D20) | M20: =K20+SUMIFS('데이터_광고'!$I$2:$I$500,'데이터_광고'!$A$2:$A$500,$A$17,'데이터_광고'!$B$2:$B$500,$A20,'데이터_광고'!$D$2:$D$500,'가정'!$A$54)/10000/'가정'!$D$54*'가정'!$B$9 | N20: =IF(B20=0,0,M20/B20) | O20: =IF(B20=0,"예산 없음",IF(I20>=$B$3,"초과",IF(I20<$D$3,"미소진","적정")))
A21: GFA 카탈로그 | B21: =SUMIFS('가정'!$C$16:$C$27,'가정'!$A$16:$A$27,$A$17,'가정'!$B$16:$B$27,$A21) | C21: =B21*'가정'!$B$7/'가정'!$B$8 | D21: =SUMIFS('데이터_광고'!$E$2:$E$500,'데이터_광고'!$A$2:$A$500,$A$17,'데이터_광고'!$B$2:$B$500,$A21)/10000 | E21: =IF(C21=0,0,D21/C21) | F21: =IF(B21=0,0,D21/B21) | G21: =B21-D21 | H21: =D21+SUMIFS('데이터_광고'!$E$2:$E$500,'데이터_광고'!$A$2:$A$500,$A$17,'데이터_광고'!$B$2:$B$500,$A21,'데이터_광고'!$D$2:$D$500,'가정'!$A$54)/10000/'가정'!$D$54*'가정'!$B$9 | I21: =IF(B21=0,0,H21/B21) | J21: =SUMIFS('데이터_광고'!$H$2:$H$500,'데이터_광고'!$A$2:$A$500,$A$17,'데이터_광고'!$B$2:$B$500,$A21) | K21: =SUMIFS('데이터_광고'!$I$2:$I$500,'데이터_광고'!$A$2:$A$500,$A$17,'데이터_광고'!$B$2:$B$500,$A21)/10000 | L21: =IF(D21=0,0,K21/D21) | M21: =K21+SUMIFS('데이터_광고'!$I$2:$I$500,'데이터_광고'!$A$2:$A$500,$A$17,'데이터_광고'!$B$2:$B$500,$A21,'데이터_광고'!$D$2:$D$500,'가정'!$A$54)/10000/'가정'!$D$54*'가정'!$B$9 | N21: =IF(B21=0,0,M21/B21) | O21: =IF(B21=0,"예산 없음",IF(I21>=$B$3,"초과",IF(I21<$D$3,"미소진","적정")))
A22: GFA 전환 | B22: =SUMIFS('가정'!$C$16:$C$27,'가정'!$A$16:$A$27,$A$17,'가정'!$B$16:$B$27,$A22) | C22: =B22*'가정'!$B$7/'가정'!$B$8 | D22: =SUMIFS('데이터_광고'!$E$2:$E$500,'데이터_광고'!$A$2:$A$500,$A$17,'데이터_광고'!$B$2:$B$500,$A22)/10000 | E22: =IF(C22=0,0,D22/C22) | F22: =IF(B22=0,0,D22/B22) | G22: =B22-D22 | H22: =D22+SUMIFS('데이터_광고'!$E$2:$E$500,'데이터_광고'!$A$2:$A$500,$A$17,'데이터_광고'!$B$2:$B$500,$A22,'데이터_광고'!$D$2:$D$500,'가정'!$A$54)/10000/'가정'!$D$54*'가정'!$B$9 | I22: =IF(B22=0,0,H22/B22) | J22: =SUMIFS('데이터_광고'!$H$2:$H$500,'데이터_광고'!$A$2:$A$500,$A$17,'데이터_광고'!$B$2:$B$500,$A22) | K22: =SUMIFS('데이터_광고'!$I$2:$I$500,'데이터_광고'!$A$2:$A$500,$A$17,'데이터_광고'!$B$2:$B$500,$A22)/10000 | L22: =IF(D22=0,0,K22/D22) | M22: =K22+SUMIFS('데이터_광고'!$I$2:$I$500,'데이터_광고'!$A$2:$A$500,$A$17,'데이터_광고'!$B$2:$B$500,$A22,'데이터_광고'!$D$2:$D$500,'가정'!$A$54)/10000/'가정'!$D$54*'가정'!$B$9 | N22: =IF(B22=0,0,M22/B22) | O22: =IF(B22=0,"예산 없음",IF(I22>=$B$3,"초과",IF(I22<$D$3,"미소진","적정")))
A23: 메타 스스 | B23: =SUMIFS('가정'!$C$16:$C$27,'가정'!$A$16:$A$27,$A$17,'가정'!$B$16:$B$27,$A23) | C23: =B23*'가정'!$B$7/'가정'!$B$8 | D23: =SUMIFS('데이터_광고'!$E$2:$E$500,'데이터_광고'!$A$2:$A$500,$A$17,'데이터_광고'!$B$2:$B$500,$A23)/10000 | E23: =IF(C23=0,0,D23/C23) | F23: =IF(B23=0,0,D23/B23) | G23: =B23-D23 | H23: =D23+SUMIFS('데이터_광고'!$E$2:$E$500,'데이터_광고'!$A$2:$A$500,$A$17,'데이터_광고'!$B$2:$B$500,$A23,'데이터_광고'!$D$2:$D$500,'가정'!$A$54)/10000/'가정'!$D$54*'가정'!$B$9 | I23: =IF(B23=0,0,H23/B23) | J23: =SUMIFS('데이터_광고'!$H$2:$H$500,'데이터_광고'!$A$2:$A$500,$A$17,'데이터_광고'!$B$2:$B$500,$A23) | K23: =SUMIFS('데이터_광고'!$I$2:$I$500,'데이터_광고'!$A$2:$A$500,$A$17,'데이터_광고'!$B$2:$B$500,$A23)/10000 | L23: =IF(D23=0,0,K23/D23) | M23: =K23+SUMIFS('데이터_광고'!$I$2:$I$500,'데이터_광고'!$A$2:$A$500,$A$17,'데이터_광고'!$B$2:$B$500,$A23,'데이터_광고'!$D$2:$D$500,'가정'!$A$54)/10000/'가정'!$D$54*'가정'!$B$9 | N23: =IF(B23=0,0,M23/B23) | O23: =IF(B23=0,"예산 없음",IF(I23>=$B$3,"초과",IF(I23<$D$3,"미소진","적정")))
A24: 메타 자사몰 | B24: =SUMIFS('가정'!$C$16:$C$27,'가정'!$A$16:$A$27,$A$17,'가정'!$B$16:$B$27,$A24) | C24: =B24*'가정'!$B$7/'가정'!$B$8 | D24: =SUMIFS('데이터_광고'!$E$2:$E$500,'데이터_광고'!$A$2:$A$500,$A$17,'데이터_광고'!$B$2:$B$500,$A24)/10000 | E24: =IF(C24=0,0,D24/C24) | F24: =IF(B24=0,0,D24/B24) | G24: =B24-D24 | H24: =D24+SUMIFS('데이터_광고'!$E$2:$E$500,'데이터_광고'!$A$2:$A$500,$A$17,'데이터_광고'!$B$2:$B$500,$A24,'데이터_광고'!$D$2:$D$500,'가정'!$A$54)/10000/'가정'!$D$54*'가정'!$B$9 | I24: =IF(B24=0,0,H24/B24) | J24: =SUMIFS('데이터_광고'!$H$2:$H$500,'데이터_광고'!$A$2:$A$500,$A$17,'데이터_광고'!$B$2:$B$500,$A24) | K24: =SUMIFS('데이터_광고'!$I$2:$I$500,'데이터_광고'!$A$2:$A$500,$A$17,'데이터_광고'!$B$2:$B$500,$A24)/10000 | L24: =IF(D24=0,0,K24/D24) | M24: =K24+SUMIFS('데이터_광고'!$I$2:$I$500,'데이터_광고'!$A$2:$A$500,$A$17,'데이터_광고'!$B$2:$B$500,$A24,'데이터_광고'!$D$2:$D$500,'가정'!$A$54)/10000/'가정'!$D$54*'가정'!$B$9 | N24: =IF(B24=0,0,M24/B24) | O24: =IF(B24=0,"예산 없음",IF(I24>=$B$3,"초과",IF(I24<$D$3,"미소진","적정")))
A25: 브랜드검색 (정액, 예산표 외) | B25: ='가정'!$B$38*'가정'!$B$8/10000 | C25: =B25*'가정'!$B$7/'가정'!$B$8 | D25: =SUMIFS('데이터_광고'!$E$2:$E$500,'데이터_광고'!$A$2:$A$500,$A$17,'데이터_광고'!$B$2:$B$500,"브랜드검색")/10000 | E25: =IF(C25=0,0,D25/C25) | F25: =IF(B25=0,0,D25/B25) | G25: =B25-D25 | H25: =D25+SUMIFS('데이터_광고'!$E$2:$E$500,'데이터_광고'!$A$2:$A$500,$A$17,'데이터_광고'!$B$2:$B$500,"브랜드검색",'데이터_광고'!$D$2:$D$500,'가정'!$A$54)/10000/'가정'!$D$54*'가정'!$B$9 | I25: =IF(B25=0,0,H25/B25) | J25: =SUMIFS('데이터_광고'!$H$2:$H$500,'데이터_광고'!$A$2:$A$500,$A$17,'데이터_광고'!$B$2:$B$500,"브랜드검색") | K25: =SUMIFS('데이터_광고'!$I$2:$I$500,'데이터_광고'!$A$2:$A$500,$A$17,'데이터_광고'!$B$2:$B$500,"브랜드검색")/10000 | L25: =IF(D25=0,0,K25/D25) | M25: =K25+SUMIFS('데이터_광고'!$I$2:$I$500,'데이터_광고'!$A$2:$A$500,$A$17,'데이터_광고'!$B$2:$B$500,"브랜드검색",'데이터_광고'!$D$2:$D$500,'가정'!$A$54)/10000/'가정'!$D$54*'가정'!$B$9 | N25: =IF(B25=0,0,M25/B25) | O25: =IF(B25=0,"예산 없음",IF(I25>=$B$3,"초과",IF(I25<$D$3,"미소진","적정")))
A26: 로지오가닉 합계 (예산표 기준, 브랜드검색 제외) | B26: =SUM(B19:B24) | C26: =B26*'가정'!$B$7/'가정'!$B$8 | D26: =SUM(D19:D24) | E26: =IF(C26=0,0,D26/C26) | F26: =IF(B26=0,0,D26/B26) | G26: =B26-D26 | H26: =SUM(H19:H24) | I26: =IF(B26=0,0,H26/B26) | J26: =SUM(J19:J24) | K26: =SUM(K19:K24) | L26: =IF(D26=0,0,K26/D26) | M26: =SUM(M19:M24) | N26: =IF(B26=0,0,M26/B26) | O26: =IF(B26=0,"예산 없음",IF(I26>=$B$3,"초과",IF(I26<$D$3,"미소진","적정")))
A27: 로지오가닉 합계 (브랜드검색 포함) | B27: =B26+B25 | C27: =B27*'가정'!$B$7/'가정'!$B$8 | D27: =D26+D25 | E27: =IF(C27=0,0,D27/C27) | F27: =IF(B27=0,0,D27/B27) | G27: =B27-D27 | H27: =H26+H25 | I27: =IF(B27=0,0,H27/B27) | J27: =J26+J25 | K27: =K26+K25 | L27: =IF(D27=0,0,K27/D27) | M27: =M26+M25 | N27: =IF(B27=0,0,M27/B27) | O27: =IF(B27=0,"예산 없음",IF(I27>=$B$3,"초과",IF(I27<$D$3,"미소진","적정")))
A29: 전체 합계 (브랜드검색 포함) | B29: =B15+B27 | C29: =B29*'가정'!$B$7/'가정'!$B$8 | D29: =D15+D27 | E29: =IF(C29=0,0,D29/C29) | F29: =IF(B29=0,0,D29/B29) | G29: =B29-D29 | H29: =H15+H27 | I29: =IF(B29=0,0,H29/B29) | J29: =J15+J27 | K29: =K15+K27 | L29: =IF(D29=0,0,K29/D29) | M29: =M15+M27 | N29: =IF(B29=0,0,M29/B29) | O29: =IF(I29>=$B$3,"초과",IF(I29<$D$3,"미소진","적정"))
A31: ="· 아넬라: 월 예산 "&TEXT(B14,"#,##0")&"만원 중 28일간 "&TEXT(D14,"#,##0")&"만원 집행(일할 대비 "&TEXT(E14,"0%")&"), 월말 예상 소진율 "&TEXT(I14,"0%")&". 집행 대비 매출 "&TEXT(K14,"#,##0")&"만원(ROAS "&TEXT(L14,"#,##0%")&", 브랜드검색 제외)."
A32: ="· 로지오가닉: 월 예산 "&TEXT(B26,"#,##0")&"만원 중 28일간 "&TEXT(D26,"#,##0")&"만원 집행(일할 대비 "&TEXT(E26,"0%")&"), 월말 예상 소진율 "&TEXT(I26,"0%")&". 집행 대비 매출 "&TEXT(K26,"#,##0")&"만원(ROAS "&TEXT(L26,"#,##0%")&", 브랜드검색 제외)."
A33: 브랜드검색은 정액 상품이라 월 예산(88만원×31/30)과 집행이 거의 같고 매출이 커서, 브랜드검색 포함 합계의 ROAS가 높게 나옵니다. 매체별 예산 소진 판단은 예산표 기준(브랜드검색 제외) 합계를 보세요.
A34: 월말 예상은 넾다세일 구간(10/26~28) 일평균을 3일 더 이은 값입니다. GFA 전환(로지)은 10월 예산이 0이라 소진율이 계산되지 않고, 10/26부터 넾다세일 한정으로 집행됐습니다.

Sheet 자사몰_매출
A1: 자사몰 10월 매출 (브랜드별) 과 메타 시크릿링크 광고
A2: 금액은 만원. 판매합계는 파일 값 그대로이며, 상품명에 "시크릿 특가"가 붙은 상품은 메타 시크릿링크 광고 유입 상품으로 봅니다. 파일에 기간이 없어 10월로 보았습니다.
A5: 브랜드별 자사몰 매출
A6: 구분 | B6: 결제수량 | C6: 환불수량 | D6: 환불률 | E6: 판매수량 | F6: 판매합계 | G6: 시크릿특가 매출 | H6: 시크릿특가 비중 | I6: 첫구매 전용 매출 | J6: 첫구매 전용 비중 | K6: 그 외 매출
A7: 아넬라 | B7: =SUMIFS('데이터_자사몰'!$D$2:$D$300,'데이터_자사몰'!$H$2:$H$300,"아넬라") | C7: =SUMIFS('데이터_자사몰'!$E$2:$E$300,'데이터_자사몰'!$H$2:$H$300,"아넬라") | D7: =IF(B7=0,0,C7/B7) | E7: =SUMIFS('데이터_자사몰'!$F$2:$F$300,'데이터_자사몰'!$H$2:$H$300,"아넬라") | F7: =SUMIFS('데이터_자사몰'!$G$2:$G$300,'데이터_자사몰'!$H$2:$H$300,"아넬라")/10000 | G7: =SUMIFS('데이터_자사몰'!$G$2:$G$300,'데이터_자사몰'!$H$2:$H$300,"아넬라",'데이터_자사몰'!$I$2:$I$300,"시크릿특가")/10000 | H7: =IF(F7=0,0,G7/F7) | I7: =SUMIFS('데이터_자사몰'!$G$2:$G$300,'데이터_자사몰'!$H$2:$H$300,"아넬라",'데이터_자사몰'!$I$2:$I$300,"첫구매전용")/10000 | J7: =IF(F7=0,0,I7/F7) | K7: =F7-G7-I7
A8: 로지오가닉 | B8: =SUMIFS('데이터_자사몰'!$D$2:$D$300,'데이터_자사몰'!$H$2:$H$300,"로지오가닉") | C8: =SUMIFS('데이터_자사몰'!$E$2:$E$300,'데이터_자사몰'!$H$2:$H$300,"로지오가닉") | D8: =IF(B8=0,0,C8/B8) | E8: =SUMIFS('데이터_자사몰'!$F$2:$F$300,'데이터_자사몰'!$H$2:$H$300,"로지오가닉") | F8: =SUMIFS('데이터_자사몰'!$G$2:$G$300,'데이터_자사몰'!$H$2:$H$300,"로지오가닉")/10000 | G8: =SUMIFS('데이터_자사몰'!$G$2:$G$300,'데이터_자사몰'!$H$2:$H$300,"로지오가닉",'데이터_자사몰'!$I$2:$I$300,"시크릿특가")/10000 | H8: =IF(F8=0,0,G8/F8) | I8: =SUMIFS('데이터_자사몰'!$G$2:$G$300,'데이터_자사몰'!$H$2:$H$300,"로지오가닉",'데이터_자사몰'!$I$2:$I$300,"첫구매전용")/10000 | J8: =IF(F8=0,0,I8/F8) | K8: =F8-G8-I8
A9: 공통 (전품목 맛보기팩) | B9: =SUMIFS('데이터_자사몰'!$D$2:$D$300,'데이터_자사몰'!$H$2:$H$300,"공통") | C9: =SUMIFS('데이터_자사몰'!$E$2:$E$300,'데이터_자사몰'!$H$2:$H$300,"공통") | D9: =IF(B9=0,0,C9/B9) | E9: =SUMIFS('데이터_자사몰'!$F$2:$F$300,'데이터_자사몰'!$H$2:$H$300,"공통") | F9: =SUMIFS('데이터_자사몰'!$G$2:$G$300,'데이터_자사몰'!$H$2:$H$300,"공통")/10000 | G9: =SUMIFS('데이터_자사몰'!$G$2:$G$300,'데이터_자사몰'!$H$2:$H$300,"공통",'데이터_자사몰'!$I$2:$I$300,"시크릿특가")/10000 | H9: =IF(F9=0,0,G9/F9) | I9: =SUMIFS('데이터_자사몰'!$G$2:$G$300,'데이터_자사몰'!$H$2:$H$300,"공통",'데이터_자사몰'!$I$2:$I$300,"첫구매전용")/10000 | J9: =IF(F9=0,0,I9/F9) | K9: =F9-G9-I9
A10: 합계 | B10: =SUM(B7:B9) | C10: =SUM(C7:C9) | D10: =IF(B10=0,0,C10/B10) | E10: =SUM(E7:E9) | F10: =SUM(F7:F9) | G10: =SUM(G7:G9) | H10: =IF(F10=0,0,G10/F10) | I10: =SUM(I7:I9) | J10: =IF(F10=0,0,I10/F10) | K10: =F10-G10-I10
A11: 브랜드 구분은 상품명에 "아넬라"/"로지오가닉"이 있는지로 나눴습니다. 두 브랜드가 함께 적힌 상품(신규회원 한정 맛보기팩)은 공통으로 따로 뒀습니다.
A13: 메타 시크릿링크 광고 vs 자사몰 시크릿특가 실매출
A14: 브랜드 | B14: 시크릿링크 광고비 | C14: 메타 보고 매출 | D14: 시크릿특가 실매출 | E14: 보고 ÷ 실매출 | F14: 보고 ROAS | G14: 실매출 ROAS | H14: 메타 자사몰 전체 광고비 | I14: 자사몰 브랜드 전체 매출 | J14: 자사몰 매출 ÷ 전체 광고비
A15: 아넬라 | B15: =SUMIFS('데이터_광고'!$E$2:$E$500,'데이터_광고'!$A$2:$A$500,$A15,'데이터_광고'!$B$2:$B$500,"메타 자사몰",'데이터_광고'!$C$2:$C$500,"*시크릿링크*")/10000 | C15: =SUMIFS('데이터_광고'!$I$2:$I$500,'데이터_광고'!$A$2:$A$500,$A15,'데이터_광고'!$B$2:$B$500,"메타 자사몰",'데이터_광고'!$C$2:$C$500,"*시크릿링크*")/10000 | D15: =G7 | E15: =IF(D15=0,0,C15/D15) | F15: =IF(B15=0,0,C15/B15) | G15: =IF(B15=0,0,D15/B15) | H15: =SUMIFS('데이터_광고'!$E$2:$E$500,'데이터_광고'!$A$2:$A$500,$A15,'데이터_광고'!$B$2:$B$500,"메타 자사몰")/10000 | I15: =F7 | J15: =IF(H15=0,0,I15/H15)
A16: 로지오가닉 | B16: =SUMIFS('데이터_광고'!$E$2:$E$500,'데이터_광고'!$A$2:$A$500,$A16,'데이터_광고'!$B$2:$B$500,"메타 자사몰",'데이터_광고'!$C$2:$C$500,"*시크릿링크*")/10000 | C16: =SUMIFS('데이터_광고'!$I$2:$I$500,'데이터_광고'!$A$2:$A$500,$A16,'데이터_광고'!$B$2:$B$500,"메타 자사몰",'데이터_광고'!$C$2:$C$500,"*시크릿링크*")/10000 | D16: =G8 | E16: =IF(D16=0,0,C16/D16) | F16: =IF(B16=0,0,C16/B16) | G16: =IF(B16=0,0,D16/B16) | H16: =SUMIFS('데이터_광고'!$E$2:$E$500,'데이터_광고'!$A$2:$A$500,$A16,'데이터_광고'!$B$2:$B$500,"메타 자사몰")/10000 | I16: =F8 | J16: =IF(H16=0,0,I16/H16)
A18: 시크릿링크 광고비는 캠페인명에 "시크릿링크"가 들어간 메타 자사몰 캠페인만 합산했습니다(아넬라 웰컴박스 제외). 메타 보고 매출이 실매출보다 큰 것은 귀속 기준 차이(조회 후 전환 등) 또는 환불·할인 반영 차이일 수 있으며, 판매합계가 쿠폰·할인을 반영한 실결제 기준인지는 확인이 필요합니다.
A20: 상품별 상위 (판매합계 순)
A21: 순위 | B21: 상품명 | F21: 판매합계(만원) | G21: 브랜드 | H21: 구분
A22: 1 | B22: ='데이터_자사몰'!B4 | F22: ='데이터_자사몰'!G4/10000 | G22: ='데이터_자사몰'!H4 | H22: ='데이터_자사몰'!I4
A23: 2 | B23: ='데이터_자사몰'!B2 | F23: ='데이터_자사몰'!G2/10000 | G23: ='데이터_자사몰'!H2 | H23: ='데이터_자사몰'!I2
A24: 3 | B24: ='데이터_자사몰'!B3 | F24: ='데이터_자사몰'!G3/10000 | G24: ='데이터_자사몰'!H3 | H24: ='데이터_자사몰'!I3
A25: 4 | B25: ='데이터_자사몰'!B9 | F25: ='데이터_자사몰'!G9/10000 | G25: ='데이터_자사몰'!H9 | H25: ='데이터_자사몰'!I9
A26: 5 | B26: ='데이터_자사몰'!B8 | F26: ='데이터_자사몰'!G8/10000 | G26: ='데이터_자사몰'!H8 | H26: ='데이터_자사몰'!I8
A27: 6 | B27: ='데이터_자사몰'!B10 | F27: ='데이터_자사몰'!G10/10000 | G27: ='데이터_자사몰'!H10 | H27: ='데이터_자사몰'!I10
A28: 7 | B28: ='데이터_자사몰'!B6 | F28: ='데이터_자사몰'!G6/10000 | G28: ='데이터_자사몰'!H6 | H28: ='데이터_자사몰'!I6
A29: 8 | B29: ='데이터_자사몰'!B17 | F29: ='데이터_자사몰'!G17/10000 | G29: ='데이터_자사몰'!H17 | H29: ='데이터_자사몰'!I17
A30: 9 | B30: ='데이터_자사몰'!B14 | F30: ='데이터_자사몰'!G14/10000 | G30: ='데이터_자사몰'!H14 | H30: ='데이터_자사몰'!I14
A31: 10 | B31: ='데이터_자사몰'!B7 | F31: ='데이터_자사몰'!G7/10000 | G31: ='데이터_자사몰'!H7 | H31: ='데이터_자사몰'!I7

Sheet 주차별_추이
A1: 기간별 추이 (상시/행사 구분)
A2: 모든 값은 데이터 시트의 SUMIFS 수식입니다. 기간 구분은 가정 시트에서 바꿀 수 있습니다. 광고비에는 브랜드검색 정액(일할)이 포함됩니다.
A4: 아넬라 | B4: 기간별 광고 성과와 스마트스토어 매출
A5: 지표 | B5: ='가정'!A50 | C5: ='가정'!A51 | D5: ='가정'!A52 | E5: ='가정'!A53 | F5: ='가정'!A54 | G5: 10월 누계 | H5: 상시 구간 | I5: 행사 구간
A6: 기간 | B6: =TEXT('가정'!B50,"m/d")&"~"&TEXT('가정'!C50,"m/d") | C6: =TEXT('가정'!B51,"m/d")&"~"&TEXT('가정'!C51,"m/d") | D6: =TEXT('가정'!B52,"m/d")&"~"&TEXT('가정'!C52,"m/d") | E6: =TEXT('가정'!B53,"m/d")&"~"&TEXT('가정'!C53,"m/d") | F6: =TEXT('가정'!B54,"m/d")&"~"&TEXT('가정'!C54,"m/d") | G6: =TEXT('가정'!B5,"m/d")&"~"&TEXT('가정'!B6,"m/d") | H6: 상시 | I6: 행사
A7: 구분 | B7: ='가정'!E50 | C7: ='가정'!E51 | D7: ='가정'!E52 | E7: ='가정'!E53 | F7: ='가정'!E54 | G7: - | H7: 상시 | I7: 행사
A8: 일수 | B8: ='가정'!D50 | C8: ='가정'!D51 | D8: ='가정'!D52 | E8: ='가정'!D53 | F8: ='가정'!D54 | G8: =SUM(B8:F8) | H8: =SUMIF($B$7:$F$7,H$7,$B8:$F8) | I8: =SUMIF($B$7:$F$7,I$7,$B8:$F8)
A9: 광고비(원) | B9: =SUMIFS('데이터_광고'!$E$2:$E$500,'데이터_광고'!$A$2:$A$500,$A$4,'데이터_광고'!$D$2:$D$500,B$5) | C9: =SUMIFS('데이터_광고'!$E$2:$E$500,'데이터_광고'!$A$2:$A$500,$A$4,'데이터_광고'!$D$2:$D$500,C$5) | D9: =SUMIFS('데이터_광고'!$E$2:$E$500,'데이터_광고'!$A$2:$A$500,$A$4,'데이터_광고'!$D$2:$D$500,D$5) | E9: =SUMIFS('데이터_광고'!$E$2:$E$500,'데이터_광고'!$A$2:$A$500,$A$4,'데이터_광고'!$D$2:$D$500,E$5) | F9: =SUMIFS('데이터_광고'!$E$2:$E$500,'데이터_광고'!$A$2:$A$500,$A$4,'데이터_광고'!$D$2:$D$500,F$5) | G9: =SUM(B9:F9) | H9: =SUMIF($B$7:$F$7,H$7,$B9:$F9) | I9: =SUMIF($B$7:$F$7,I$7,$B9:$F9)
A10: 매출(원) | B10: =SUMIFS('데이터_광고'!$I$2:$I$500,'데이터_광고'!$A$2:$A$500,$A$4,'데이터_광고'!$D$2:$D$500,B$5) | C10: =SUMIFS('데이터_광고'!$I$2:$I$500,'데이터_광고'!$A$2:$A$500,$A$4,'데이터_광고'!$D$2:$D$500,C$5) | D10: =SUMIFS('데이터_광고'!$I$2:$I$500,'데이터_광고'!$A$2:$A$500,$A$4,'데이터_광고'!$D$2:$D$500,D$5) | E10: =SUMIFS('데이터_광고'!$I$2:$I$500,'데이터_광고'!$A$2:$A$500,$A$4,'데이터_광고'!$D$2:$D$500,E$5) | F10: =SUMIFS('데이터_광고'!$I$2:$I$500,'데이터_광고'!$A$2:$A$500,$A$4,'데이터_광고'!$D$2:$D$500,F$5) | G10: =SUM(B10:F10) | H10: =SUMIF($B$7:$F$7,H$7,$B10:$F10) | I10: =SUMIF($B$7:$F$7,I$7,$B10:$F10)
A11: ROAS | B11: =IF(B9=0,0,B10/B9) | C11: =IF(C9=0,0,C10/C9) | D11: =IF(D9=0,0,D10/D9) | E11: =IF(E9=0,0,E10/E9) | F11: =IF(F9=0,0,F10/F9) | G11: =IF(G9=0,0,G10/G9) | H11: =IF(H9=0,0,H10/H9) | I11: =IF(I9=0,0,I10/I9)
A12: 구매(건) | B12: =SUMIFS('데이터_광고'!$H$2:$H$500,'데이터_광고'!$A$2:$A$500,$A$4,'데이터_광고'!$D$2:$D$500,B$5) | C12: =SUMIFS('데이터_광고'!$H$2:$H$500,'데이터_광고'!$A$2:$A$500,$A$4,'데이터_광고'!$D$2:$D$500,C$5) | D12: =SUMIFS('데이터_광고'!$H$2:$H$500,'데이터_광고'!$A$2:$A$500,$A$4,'데이터_광고'!$D$2:$D$500,D$5) | E12: =SUMIFS('데이터_광고'!$H$2:$H$500,'데이터_광고'!$A$2:$A$500,$A$4,'데이터_광고'!$D$2:$D$500,E$5) | F12: =SUMIFS('데이터_광고'!$H$2:$H$500,'데이터_광고'!$A$2:$A$500,$A$4,'데이터_광고'!$D$2:$D$500,F$5) | G12: =SUM(B12:F12) | H12: =SUMIF($B$7:$F$7,H$7,$B12:$F12) | I12: =SUMIF($B$7:$F$7,I$7,$B12:$F12)
A13: 클릭 | B13: =SUMIFS('데이터_광고'!$G$2:$G$500,'데이터_광고'!$A$2:$A$500,$A$4,'데이터_광고'!$D$2:$D$500,B$5) | C13: =SUMIFS('데이터_광고'!$G$2:$G$500,'데이터_광고'!$A$2:$A$500,$A$4,'데이터_광고'!$D$2:$D$500,C$5) | D13: =SUMIFS('데이터_광고'!$G$2:$G$500,'데이터_광고'!$A$2:$A$500,$A$4,'데이터_광고'!$D$2:$D$500,D$5) | E13: =SUMIFS('데이터_광고'!$G$2:$G$500,'데이터_광고'!$A$2:$A$500,$A$4,'데이터_광고'!$D$2:$D$500,E$5) | F13: =SUMIFS('데이터_광고'!$G$2:$G$500,'데이터_광고'!$A$2:$A$500,$A$4,'데이터_광고'!$D$2:$D$500,F$5) | G13: =SUM(B13:F13) | H13: =SUMIF($B$7:$F$7,H$7,$B13:$F13) | I13: =SUMIF($B$7:$F$7,I$7,$B13:$F13)
A14: 객단가(원) | B14: =IF(B12=0,0,B10/B12) | C14: =IF(C12=0,0,C10/C12) | D14: =IF(D12=0,0,D10/D12) | E14: =IF(E12=0,0,E10/E12) | F14: =IF(F12=0,0,F10/F12) | G14: =IF(G12=0,0,G10/G12) | H14: =IF(H12=0,0,H10/H12) | I14: =IF(I12=0,0,I10/I12)
A15: 일평균 광고비(원) | B15: =IF(B8=0,0,B9/B8) | C15: =IF(C8=0,0,C9/C8) | D15: =IF(D8=0,0,D9/D8) | E15: =IF(E8=0,0,E9/E8) | F15: =IF(F8=0,0,F9/F8) | G15: =IF(G8=0,0,G9/G8) | H15: =IF(H8=0,0,H9/H8) | I15: =IF(I8=0,0,I9/I8)
A16: 일평균 매출(원) | B16: =IF(B8=0,0,B10/B8) | C16: =IF(C8=0,0,C10/C8) | D16: =IF(D8=0,0,D10/D8) | E16: =IF(E8=0,0,E10/E8) | F16: =IF(F8=0,0,F10/F8) | G16: =IF(G8=0,0,G10/G8) | H16: =IF(H8=0,0,H10/H8) | I16: =IF(I8=0,0,I10/I8)
A17: 스마트스토어 일반상품 순매출(원) | B17: =SUMIFS('데이터_SS일별'!$F$2:$F$400,'데이터_SS일별'!$A$2:$A$400,$A$4,'데이터_SS일별'!$C$2:$C$400,"일반",'데이터_SS일별'!$B$2:$B$400,">="&'가정'!B50,'데이터_SS일별'!$B$2:$B$400,"<="&'가정'!C50) | C17: =SUMIFS('데이터_SS일별'!$F$2:$F$400,'데이터_SS일별'!$A$2:$A$400,$A$4,'데이터_SS일별'!$C$2:$C$400,"일반",'데이터_SS일별'!$B$2:$B$400,">="&'가정'!B51,'데이터_SS일별'!$B$2:$B$400,"<="&'가정'!C51) | D17: =SUMIFS('데이터_SS일별'!$F$2:$F$400,'데이터_SS일별'!$A$2:$A$400,$A$4,'데이터_SS일별'!$C$2:$C$400,"일반",'데이터_SS일별'!$B$2:$B$400,">="&'가정'!B52,'데이터_SS일별'!$B$2:$B$400,"<="&'가정'!C52) | E17: =SUMIFS('데이터_SS일별'!$F$2:$F$400,'데이터_SS일별'!$A$2:$A$400,$A$4,'데이터_SS일별'!$C$2:$C$400,"일반",'데이터_SS일별'!$B$2:$B$400,">="&'가정'!B53,'데이터_SS일별'!$B$2:$B$400,"<="&'가정'!C53) | F17: =SUMIFS('데이터_SS일별'!$F$2:$F$400,'데이터_SS일별'!$A$2:$A$400,$A$4,'데이터_SS일별'!$C$2:$C$400,"일반",'데이터_SS일별'!$B$2:$B$400,">="&'가정'!B54,'데이터_SS일별'!$B$2:$B$400,"<="&'가정'!C54) | G17: =SUM(B17:F17) | H17: =SUMIF($B$7:$F$7,H$7,$B17:$F17) | I17: =SUMIF($B$7:$F$7,I$7,$B17:$F17)
A18: (참고) 공동구매 순매출, 집계 제외분(원) | B18: =SUMIFS('데이터_SS일별'!$F$2:$F$400,'데이터_SS일별'!$A$2:$A$400,$A$4,'데이터_SS일별'!$C$2:$C$400,"공구",'데이터_SS일별'!$B$2:$B$400,">="&'가정'!B50,'데이터_SS일별'!$B$2:$B$400,"<="&'가정'!C50) | C18: =SUMIFS('데이터_SS일별'!$F$2:$F$400,'데이터_SS일별'!$A$2:$A$400,$A$4,'데이터_SS일별'!$C$2:$C$400,"공구",'데이터_SS일별'!$B$2:$B$400,">="&'가정'!B51,'데이터_SS일별'!$B$2:$B$400,"<="&'가정'!C51) | D18: =SUMIFS('데이터_SS일별'!$F$2:$F$400,'데이터_SS일별'!$A$2:$A$400,$A$4,'데이터_SS일별'!$C$2:$C$400,"공구",'데이터_SS일별'!$B$2:$B$400,">="&'가정'!B52,'데이터_SS일별'!$B$2:$B$400,"<="&'가정'!C52) | E18: =SUMIFS('데이터_SS일별'!$F$2:$F$400,'데이터_SS일별'!$A$2:$A$400,$A$4,'데이터_SS일별'!$C$2:$C$400,"공구",'데이터_SS일별'!$B$2:$B$400,">="&'가정'!B53,'데이터_SS일별'!$B$2:$B$400,"<="&'가정'!C53) | F18: =SUMIFS('데이터_SS일별'!$F$2:$F$400,'데이터_SS일별'!$A$2:$A$400,$A$4,'데이터_SS일별'!$C$2:$C$400,"공구",'데이터_SS일별'!$B$2:$B$400,">="&'가정'!B54,'데이터_SS일별'!$B$2:$B$400,"<="&'가정'!C54) | G18: =SUM(B18:F18) | H18: =SUMIF($B$7:$F$7,H$7,$B18:$F18) | I18: =SUMIF($B$7:$F$7,I$7,$B18:$F18)
A19: 스스향 광고비(원, 메타 자사몰 제외) | B19: =B9-SUMIFS('데이터_광고'!$E$2:$E$500,'데이터_광고'!$A$2:$A$500,$A$4,'데이터_광고'!$D$2:$D$500,B$5,'데이터_광고'!$B$2:$B$500,"메타 자사몰") | C19: =C9-SUMIFS('데이터_광고'!$E$2:$E$500,'데이터_광고'!$A$2:$A$500,$A$4,'데이터_광고'!$D$2:$D$500,C$5,'데이터_광고'!$B$2:$B$500,"메타 자사몰") | D19: =D9-SUMIFS('데이터_광고'!$E$2:$E$500,'데이터_광고'!$A$2:$A$500,$A$4,'데이터_광고'!$D$2:$D$500,D$5,'데이터_광고'!$B$2:$B$500,"메타 자사몰") | E19: =E9-SUMIFS('데이터_광고'!$E$2:$E$500,'데이터_광고'!$A$2:$A$500,$A$4,'데이터_광고'!$D$2:$D$500,E$5,'데이터_광고'!$B$2:$B$500,"메타 자사몰") | F19: =F9-SUMIFS('데이터_광고'!$E$2:$E$500,'데이터_광고'!$A$2:$A$500,$A$4,'데이터_광고'!$D$2:$D$500,F$5,'데이터_광고'!$B$2:$B$500,"메타 자사몰") | G19: =SUM(B19:F19) | H19: =SUMIF($B$7:$F$7,H$7,$B19:$F19) | I19: =SUMIF($B$7:$F$7,I$7,$B19:$F19)
A20: 스마트스토어 통합 ROAS (순매출÷스스향 광고비) | B20: =IF(B19=0,0,B17/B19) | C20: =IF(C19=0,0,C17/C19) | D20: =IF(D19=0,0,D17/D19) | E20: =IF(E19=0,0,E17/E19) | F20: =IF(F19=0,0,F17/F19) | G20: =IF(G19=0,0,G17/G19) | H20: =IF(H19=0,0,H17/H19) | I20: =IF(I19=0,0,I17/I19)
A25: 로지오가닉 | B25: 기간별 광고 성과와 스마트스토어 매출
A26: 지표 | B26: ='가정'!A50 | C26: ='가정'!A51 | D26: ='가정'!A52 | E26: ='가정'!A53 | F26: ='가정'!A54 | G26: 10월 누계 | H26: 상시 구간 | I26: 행사 구간
A27: 기간 | B27: =TEXT('가정'!B50,"m/d")&"~"&TEXT('가정'!C50,"m/d") | C27: =TEXT('가정'!B51,"m/d")&"~"&TEXT('가정'!C51,"m/d") | D27: =TEXT('가정'!B52,"m/d")&"~"&TEXT('가정'!C52,"m/d") | E27: =TEXT('가정'!B53,"m/d")&"~"&TEXT('가정'!C53,"m/d") | F27: =TEXT('가정'!B54,"m/d")&"~"&TEXT('가정'!C54,"m/d") | G27: =TEXT('가정'!B5,"m/d")&"~"&TEXT('가정'!B6,"m/d") | H27: 상시 | I27: 행사
A28: 구분 | B28: ='가정'!E50 | C28: ='가정'!E51 | D28: ='가정'!E52 | E28: ='가정'!E53 | F28: ='가정'!E54 | G28: - | H28: 상시 | I28: 행사
A29: 일수 | B29: ='가정'!D50 | C29: ='가정'!D51 | D29: ='가정'!D52 | E29: ='가정'!D53 | F29: ='가정'!D54 | G29: =SUM(B29:F29) | H29: =SUMIF($B$28:$F$28,H$28,$B29:$F29) | I29: =SUMIF($B$28:$F$28,I$28,$B29:$F29)
A30: 광고비(원) | B30: =SUMIFS('데이터_광고'!$E$2:$E$500,'데이터_광고'!$A$2:$A$500,$A$25,'데이터_광고'!$D$2:$D$500,B$26) | C30: =SUMIFS('데이터_광고'!$E$2:$E$500,'데이터_광고'!$A$2:$A$500,$A$25,'데이터_광고'!$D$2:$D$500,C$26) | D30: =SUMIFS('데이터_광고'!$E$2:$E$500,'데이터_광고'!$A$2:$A$500,$A$25,'데이터_광고'!$D$2:$D$500,D$26) | E30: =SUMIFS('데이터_광고'!$E$2:$E$500,'데이터_광고'!$A$2:$A$500,$A$25,'데이터_광고'!$D$2:$D$500,E$26) | F30: =SUMIFS('데이터_광고'!$E$2:$E$500,'데이터_광고'!$A$2:$A$500,$A$25,'데이터_광고'!$D$2:$D$500,F$26) | G30: =SUM(B30:F30) | H30: =SUMIF($B$28:$F$28,H$28,$B30:$F30) | I30: =SUMIF($B$28:$F$28,I$28,$B30:$F30)
A31: 매출(원) | B31: =SUMIFS('데이터_광고'!$I$2:$I$500,'데이터_광고'!$A$2:$A$500,$A$25,'데이터_광고'!$D$2:$D$500,B$26) | C31: =SUMIFS('데이터_광고'!$I$2:$I$500,'데이터_광고'!$A$2:$A$500,$A$25,'데이터_광고'!$D$2:$D$500,C$26) | D31: =SUMIFS('데이터_광고'!$I$2:$I$500,'데이터_광고'!$A$2:$A$500,$A$25,'데이터_광고'!$D$2:$D$500,D$26) | E31: =SUMIFS('데이터_광고'!$I$2:$I$500,'데이터_광고'!$A$2:$A$500,$A$25,'데이터_광고'!$D$2:$D$500,E$26) | F31: =SUMIFS('데이터_광고'!$I$2:$I$500,'데이터_광고'!$A$2:$A$500,$A$25,'데이터_광고'!$D$2:$D$500,F$26) | G31: =SUM(B31:F31) | H31: =SUMIF($B$28:$F$28,H$28,$B31:$F31) | I31: =SUMIF($B$28:$F$28,I$28,$B31:$F31)
A32: ROAS | B32: =IF(B30=0,0,B31/B30) | C32: =IF(C30=0,0,C31/C30) | D32: =IF(D30=0,0,D31/D30) | E32: =IF(E30=0,0,E31/E30) | F32: =IF(F30=0,0,F31/F30) | G32: =IF(G30=0,0,G31/G30) | H32: =IF(H30=0,0,H31/H30) | I32: =IF(I30=0,0,I31/I30)
A33: 구매(건) | B33: =SUMIFS('데이터_광고'!$H$2:$H$500,'데이터_광고'!$A$2:$A$500,$A$25,'데이터_광고'!$D$2:$D$500,B$26) | C33: =SUMIFS('데이터_광고'!$H$2:$H$500,'데이터_광고'!$A$2:$A$500,$A$25,'데이터_광고'!$D$2:$D$500,C$26) | D33: =SUMIFS('데이터_광고'!$H$2:$H$500,'데이터_광고'!$A$2:$A$500,$A$25,'데이터_광고'!$D$2:$D$500,D$26) | E33: =SUMIFS('데이터_광고'!$H$2:$H$500,'데이터_광고'!$A$2:$A$500,$A$25,'데이터_광고'!$D$2:$D$500,E$26) | F33: =SUMIFS('데이터_광고'!$H$2:$H$500,'데이터_광고'!$A$2:$A$500,$A$25,'데이터_광고'!$D$2:$D$500,F$26) | G33: =SUM(B33:F33) | H33: =SUMIF($B$28:$F$28,H$28,$B33:$F33) | I33: =SUMIF($B$28:$F$28,I$28,$B33:$F33)
A34: 클릭 | B34: =SUMIFS('데이터_광고'!$G$2:$G$500,'데이터_광고'!$A$2:$A$500,$A$25,'데이터_광고'!$D$2:$D$500,B$26) | C34: =SUMIFS('데이터_광고'!$G$2:$G$500,'데이터_광고'!$A$2:$A$500,$A$25,'데이터_광고'!$D$2:$D$500,C$26) | D34: =SUMIFS('데이터_광고'!$G$2:$G$500,'데이터_광고'!$A$2:$A$500,$A$25,'데이터_광고'!$D$2:$D$500,D$26) | E34: =SUMIFS('데이터_광고'!$G$2:$G$500,'데이터_광고'!$A$2:$A$500,$A$25,'데이터_광고'!$D$2:$D$500,E$26) | F34: =SUMIFS('데이터_광고'!$G$2:$G$500,'데이터_광고'!$A$2:$A$500,$A$25,'데이터_광고'!$D$2:$D$500,F$26) | G34: =SUM(B34:F34) | H34: =SUMIF($B$28:$F$28,H$28,$B34:$F34) | I34: =SUMIF($B$28:$F$28,I$28,$B34:$F34)
A35: 객단가(원) | B35: =IF(B33=0,0,B31/B33) | C35: =IF(C33=0,0,C31/C33) | D35: =IF(D33=0,0,D31/D33) | E35: =IF(E33=0,0,E31/E33) | F35: =IF(F33=0,0,F31/F33) | G35: =IF(G33=0,0,G31/G33) | H35: =IF(H33=0,0,H31/H33) | I35: =IF(I33=0,0,I31/I33)
